Workbook

Sheet Read me
A1: DVI V2 test cases: what changed in the spec since 22 September
A3: Hi Vladimir and Viktoria,
B4: We checked the Digital Inspection V2 test cases against every current source on 14 October 2026, and we would like to share what has changed, in case it helps.
B5: Our cases were written against the spec as it was on 22 September. The spec has changed a number of times since, up to version 43 on 13 October. Some cases still follow the earlier wording.
A6: Why you, Viktoria | B6: The DVI V2 team sync of 12 October says "QA on the feature squad owns writing and updating test cases", so these updates are yours to make. We have not edited any case.
A7: Why you, Vladimir | B7: Some of these cases are automated. Where the behaviour changed, the automation may still check the old behaviour.
A9: What is in each tab
A10: Cases to update | B10: One row per case and spec rule: what the spec said before, what it says now, when the spec changed it (from the spec's own change log), and what to do. "Please check" rows are cases that word the rule in their own way.
A11: Later Jira decisions | B11: Decisions made in Jira after the spec text was written. The latest decision wins, so the case should follow it.
A12: No case yet | B12: New rules, or later decisions, that no case covers yet.
A14: At a glance
A15: Case rows to update (old wording) | B15: =COUNTIF('Cases to update'!M2:M,"Update*")+COUNTIF('Cases to update'!M2:M,"The spec no longer*")
A16: Case rows to check | B16: =COUNTIF('Cases to update'!M2:M,"Please check*")
A17: Rows on automated cases | B17: =COUNTIF('Cases to update'!C2:C,"Yes")
A18: Later Jira decisions | B18: =COUNTA('Later Jira decisions'!A2:A)
A19: Rules with no case yet | B19: =COUNTA('No case yet'!A2:A)
A21: Sources
A22: The spec | B22: =HYPERLINK("https://shopview.atlassian.net/wiki/pages/viewpage.action?pageId=768507905","Confluence page 768507905, Digital Inspections V2, version 43 (13 Oct 2026)")
A23: Team sync, 12 Oct 2026 | B23: =HYPERLINK("https://shopview.slack.com/archives/C0C39T5MLMB/p1791807912692899","Milos Vasic in #fs-dvi-v2")
A24: The epic | B24: =HYPERLINK("https://shopview.atlassian.net/browse/SV-8181","SV-8181 and its tickets")
A25: The test cases | B25: =HYPERLINK("https://shopview.testrail.io/index.php?/suites/view/1&group_id=6658","TestRail folder: Digital Inspection V2")
A26: How the dates were found | B26: From the Change Log at the end of the spec. The column "How we know the date" says whether the entry names the rule or describes the change.
A28: Thank you, | B28: Bilal Muzamil

Sheet Cases to update
A1: Case | B1: Case title | C1: Automated? | D1: Who this is for | E1: Spec rule | F1: What the spec said before (22 Sep 2026) | G1: What the spec says now (version 43, 13 Oct 2026) | H1: What changed, in plain words | I1: When the spec changed | J1: Spec change log entry | K1: How we know the date | L1: Decided in Jira | M1: What to do | N1: Where in the spec
A2: =HYPERLINK("https://shopview.testrail.io/index.php?/cases/view/88507","C88507") | B2: Note required option on checkbox and per-axle fields, on by default | C2: No | D2: Viktoria (case text) | E2: S1-R2 | F2: The option will be on by default for newly added checkbox fields | G2: The option will be on by default for newly added checkbox fields, starters included | H2: The 'note required' option being on by default for newly added checkbox fields now also applies to the fields in the starter templates. | I2: between 29 Sep 2026 and 13 Oct 2026 | K2: Not named in the change log; changed between 29 Sep and 13 Oct | M2: Update the steps and expected results to match the new text. | N2: =HYPERLINK("https://shopview.atlassian.net/wiki/pages/viewpage.action?pageId=768507905","Spec page")
A3: =HYPERLINK("https://shopview.testrail.io/index.php?/cases/view/88513","C88513") | B3: Choose which work order gets the lines, or a new one, before drafting | C3: Yes | D3: Viktoria (case text) and Vladimir (automation) | E3: S2-R15 | F3: A destination that cannot take lines will keep its place in the menu and say why. A destination that silently stops being offered reads as a fault | G3: (removed from the spec) | H3: Removed: a destination that cannot take lines no longer stays in the menu with a reason; it is simply not shown. | I3: 29 Sep 2026 | J3: 29 Sep 2026: "QA contradiction pass answered" | K3: The change log entry describes this change | M3: The spec no longer has this rule. Remove or rewrite the steps and expected results that check it. Vladimir: the automation for this case may check the old behaviour. | N3: =HYPERLINK("https://shopview.atlassian.net/wiki/pages/viewpage.action?pageId=768507905","Spec page")
A4: =HYPERLINK("https://shopview.testrail.io/index.php?/cases/view/88513","C88513") | B4: Choose which work order gets the lines, or a new one, before drafting | C4: Yes | D4: Viktoria (case text) and Vladimir (automation) | E4: S2-R4 | F4: The system will offer the work order the inspection was run on only while that work order is an eligible build target. Eligible means Estimate, Approved, In Progress or Review. This document does not describe a work order as open or closed: the platform carries several competing definitions of open, and this rule names its own predicate rather than joining them | G4: The system will offer the work order the inspection was run on only while that work order is an eligible build target. Eligible means Estimate, Approved, In Progress or Review, and no invoice exists. This document does not describe a work order as open or closed: the platform carries several competing definitions of open, and this rule names its own predicate rather than joining them | H4: The inspection's own work order is offered only if it is Estimate, Approved, In Progress or Review and also has no invoice (the 'no invoice' condition is new in this rule). | I4: between 29 Sep 2026 and 2 Oct 2026 | K4: Not named in the change log; Jira SV-10792 (2 Oct 2026) already quotes the new text | M4: Update the steps and expected results to match the new text. Vladimir: the automation for this case may check the old behaviour. | N4: =HYPERLINK("https://shopview.atlassian.net/wiki/pages/viewpage.action?pageId=768507905","Spec page")
A5: =HYPERLINK("https://shopview.testrail.io/index.php?/cases/view/88513","C88513") | B5: Choose which work order gets the lines, or a new one, before drafting | C5: Yes | D5: Viktoria (case text) and Vladimir (automation) | E5: S2-R5 | F5: When the work order the inspection was run on is not an eligible build target, the system will create a new work order without asking. It is ineligible when its status is Complete, Invoiced, Paid or Declined, or when an invoice already exists. Declined counts as ineligible because lines added to a refused order would revive work the customer turned down | G5: When the work order the inspection was run on is not an eligible build target, the destination menu still opens and offers only a new work order. It is ineligible when its status is Complete, Invoiced, Paid or Declined, or when an invoice already exists. Declined counts as ineligible because lines added to a refused order would revive work the customer turned down | H5: When the inspection's own work order cannot take lines, the destination menu still opens and offers only a new work order, instead of a new work order being created without asking. | I5: 29 Sep 2026 | J5: 29 Sep 2026: "QA contradiction pass answered" | K5: The change log entry describes this change | M5: Update the steps and expected results to match the new text. Vladimir: the automation for this case may check the old behaviour. | N5: =HYPERLINK("https://shopview.atlassian.net/wiki/pages/viewpage.action?pageId=768507905","Spec page")
A6: =HYPERLINK("https://shopview.testrail.io/index.php?/cases/view/88514","C88514") | B6: A line built from an inspection behaves like any approved line | C6: Yes | D6: Viktoria (case text) and Vladimir (automation) | E6: S2-R1 | F6: Every Monitor and Not OK finding will be represented by at least one line. ShopCoach composes each line's name, description, time estimate and parts; the field label, the measured value and the technician's note are inputs to that drafting rather than the line text itself (S15) | G6: Every Monitor and Not OK finding will be represented by at least one line. ShopCoach composes each line's name, description, time estimate and parts; the field label, the measured value and the technician's note are inputs to that drafting rather than the line text itself (S15). When drafting fails, S15-E2 applies instead | H6: Adds that when ShopCoach drafting fails, the failure rule applies instead of every flagged finding getting a line. | I6: 29 Sep 2026 | J6: 29 Sep 2026: "QA contradiction pass answered" | K6: The change log entry describes this change | M6: Update the steps and expected results to match the new text. Vladimir: the automation for this case may check the old behaviour. | N6: =HYPERLINK("https://shopview.atlassian.net/wiki/pages/viewpage.action?pageId=768507905","Spec page")
A7: =HYPERLINK("https://shopview.testrail.io/index.php?/cases/view/88515","C88515") | B7: After building you land on Lines, the finding is marked done, rebuild asks | C7: No | D7: Viktoria (case text) | E7: S2-R13 | F7: If lines have already been added from this inspection, the user will be asked to confirm before adding a second set. The check is made when Add Lines is pressed, on the state at that moment | G7: An inspection is built from once. After lines have been added from it, to this work order or to a new one, no entry point offers the build action again: the completed inspection, the work order note and the asset row show the outcome instead, with a link to the work order that got the lines. The check is made again when Add Lines is pressed; if the inspection was built from elsewhere in the meantime, nothing is added and the user is told where the lines went | H7: Lines can be built from an inspection only once: instead of asking to confirm a second set, every place shows the result with a link to the work order that got the lines, and a late second Add Lines adds nothing and tells the user where the lines went. | I7: 29 Sep 2026 | J7: 29 Sep 2026: "QA contradiction pass answered" | K7: The change log entry names this rule | M7: Update the steps and expected results to match the new text. | N7: =HYPERLINK("https://shopview.atlassian.net/wiki/pages/viewpage.action?pageId=768507905","Spec page")
A8: =HYPERLINK("https://shopview.testrail.io/index.php?/cases/view/88518","C88518") | B8: Building lines with long notes, many findings, or a deleted work order | C8: Yes | D8: Viktoria (case text) and Vladimir (automation) | E8: S2-E6 | F8: If two users draft from the same inspection at once, nothing is duplicated by the drafting itself, because a draft is not a work order line. Duplication happens only if both press Add Lines, which is accepted and recoverable | G8: If two users draft from the same inspection at once, nothing is duplicated by the drafting itself, because a draft is not a work order line. When both press Add Lines, only the first adds lines; the second adds nothing and the user is told where the lines went (S2-R13) | H8: When two users both press Add Lines on the same inspection, only the first adds lines; the second adds nothing and is told where the lines went (before, both sets were added). | I8: 7 Oct 2026 | J8: 7 Oct 2026: "Leftovers from the built-once rule; file limit; submit name" | K8: The change log entry names this rule | M8: Update the steps and expected results to match the new text. Vladimir: the automation for this case may check the old behaviour. | N8: =HYPERLINK("https://shopview.atlassian.net/wiki/pages/viewpage.action?pageId=768507905","Spec page")
A9: =HYPERLINK("https://shopview.testrail.io/index.php?/cases/view/88518","C88518") | B9: Building lines with long notes, many findings, or a deleted work order | C9: Yes | D9: Viktoria (case text) and Vladimir (automation) | E9: S2-E12 | F9: If the work order the inspection was run on is deleted, the inspection survives it (S5-R21) and stays listed on the asset with a dash in its work order column. Where the lines had been added to that same work order they are gone with it, and the inspection counts as needing a work order again | G9: If the work order the inspection was run on is deleted, an inspection that has a report survives it as a read-only record (S5-E3). Lines that had been added to that work order are gone with it. The inspection does not count as needing a work order, because it can no longer be built from | H9: When the inspection's work order is deleted, only an inspection that has a report survives, as a read-only record; it no longer counts as needing a work order, because it can no longer be built from (before, it counted as needing one again). | I9: 6 Oct 2026 | J9: 6 Oct 2026: "Deleted work orders, removed inspections and splits" Also: 7 Oct 2026: "Deleted work order after a build" | K9: The change log entry describes this change | M9: Update the steps and expected results to match the new text. Vladimir: the automation for this case may check the old behaviour. | N9: =HYPERLINK("https://shopview.atlassian.net/wiki/pages/viewpage.action?pageId=768507905","Spec page")
A10: =HYPERLINK("https://shopview.testrail.io/index.php?/cases/view/88518","C88518") | B10: Building lines with long notes, many findings, or a deleted work order | C10: Yes | D10: Viktoria (case text) and Vladimir (automation) | E10: S5-R21 | F10: An inspection records the asset it was run on, stored on the inspection when it is created rather than derived through its work order. A work order carries exactly one asset and that asset can be changed later, so this tab is a record of what was inspected rather than a view that follows a later correction. Inspections that exist before this release are backfilled from their work order’s asset at migration, without which this tab cannot show history | G10: The tab lists the inspections whose work order is on this asset now, so it follows the work order when the work order's asset is changed or two assets are merged. The asset an inspection was run on is also stored on the inspection when it is created, as a record. Inspections that exist before this release are backfilled from their work order's asset at migration. When the work order has been deleted, the stored asset is used (S5-E3). Merging assets moves such inspections to the surviving asset, as it moves the work orders | H10: The asset's Inspections tab now lists the inspections whose work order is on this asset now, so it follows the work order when its asset is changed or assets are merged; the asset stored on the inspection is kept as a record and used when the work order has been deleted, and merging assets moves such inspections to the surviving asset. | I10: 5 Oct 2026 | J10: 5 Oct 2026: "Developer and QA questions answered" Also: 7 Oct 2026: "Deleted work order: outcome, footer, reopened, merge (SV-10965)" | K10: The change log entry describes this change | L10: =HYPERLINK("https://shopview.atlassian.net/browse/SV-10965","SV-10965") | M10: Update the steps and expected results to match the new text. Vladimir: the automation for this case may check the old behaviour. | N10: =HYPERLINK("https://shopview.atlassian.net/wiki/pages/viewpage.action?pageId=768507905","Spec page")
A11: =HYPERLINK("https://shopview.testrail.io/index.php?/cases/view/88520","C88520") | B11: The summary card, counts per verdict, and the section review | C11: Yes | D11: Viktoria (case text) and Vladimir (automation) | E11: S3-R4 | F11: The screen will lead with a summary card: the completion line, a count per verdict, and a findings list naming each flagged position as field, axle, row and position with the reading that earned it | G11: The screen will lead with a summary card: the completion line, a count per verdict, and a findings list naming each flagged row as field, axle and row, followed by every flagged position on it with its reading, for example 'Brake & tire measurements · Axle 1 · Tire pressure: left outer 42 psi, right outer 40 psi' | H11: The findings list on the completed screen now names each flagged row (field, axle and row) followed by every flagged position on it with its reading, instead of one entry per flagged position. | I11: 29 Sep 2026 | J11: 29 Sep 2026: "QA contradiction pass answered" | K11: The change log entry describes this change | M11: Update the steps and expected results to match the new text. Vladimir: the automation for this case may check the old behaviour. | N11: =HYPERLINK("https://shopview.atlassian.net/wiki/pages/viewpage.action?pageId=768507905","Spec page")
A12: =HYPERLINK("https://shopview.testrail.io/index.php?/cases/view/88520","C88520") | B12: The summary card, counts per verdict, and the section review | C12: Yes | D12: Viktoria (case text) and Vladimir (automation) | E12: S3-R6 | F12: With ShopCoach the card's footer will offer View PDF, Go to work order and Build lines, and a note above it will name the product once. Without ShopCoach the footer will offer View PDF and Go to work order, and the same space will carry a plain line saying the findings are on the customer report and in the work order note feed and that the lines are added on the work order | G12: With ShopCoach the card's footer will offer View PDF, Go to work order and Build lines, and a note above it will name the product once. Without ShopCoach the footer will offer View PDF and Go to work order, and the same space will carry a plain line saying the findings are on the customer report and in the work order note feed and that the lines are added on the work order. When the work order the inspection was run on has been deleted, the footer offers View PDF only, with or without ShopCoach, and no plain line; it also shows the outcome when the lines went onto another work order that still exists (S5-E3) | H12: When the inspection's work order has been deleted, the completed screen's footer offers only View PDF, with or without ShopCoach and with no explanatory line, and also shows the result if the lines went onto another work order that still exists. | I12: 7 Oct 2026 | J12: 7 Oct 2026: "Deleted work order: outcome, footer, reopened, merge (SV-10965)" Also: 7 Oct 2026: "Deleted work order after a build" | K12: The change log entry describes this change | L12: =HYPERLINK("https://shopview.atlassian.net/browse/SV-10965","SV-10965") | M12: Update the steps and expected results to match the new text. Vladimir: the automation for this case may check the old behaviour. | N12: =HYPERLINK("https://shopview.atlassian.net/wiki/pages/viewpage.action?pageId=768507905","Spec page")
A13: =HYPERLINK("https://shopview.testrail.io/index.php?/cases/view/88521","C88521") | B13: Build lines is hidden, not greyed out, until the inspection is ready | C13: No | D13: Viktoria (case text) | E13: S3-N4 | F13: If the organisation does not have ShopCoach, no build action is shown. The screen offers View PDF and a link to the work order and nothing else — the action is absent, not disabled and not behind a tooltip (S2-R0) | G13: If the organisation does not have ShopCoach, no build action is shown. The screen offers View PDF and a link to the work order and no build action — the action is absent, not disabled and not behind a tooltip (S2-R0) | H13: Wording only: without ShopCoach the screen offers View PDF, a link to the work order and 'no build action' instead of 'nothing else'. | I13: between 29 Sep 2026 and 13 Oct 2026 | K13: Not named in the change log; changed between 29 Sep and 13 Oct | M13: Update the steps and expected results to match the new text. | N13: =HYPERLINK("https://shopview.atlassian.net/wiki/pages/viewpage.action?pageId=768507905","Spec page")
A14: =HYPERLINK("https://shopview.testrail.io/index.php?/cases/view/88522","C88522") | B14: Building lines when the work order is deleted, built twice, or reopened | C14: Yes | D14: Viktoria (case text) and Vladimir (automation) | E14: S2-R13 | F14: If lines have already been added from this inspection, the user will be asked to confirm before adding a second set. The check is made when Add Lines is pressed, on the state at that moment | G14: An inspection is built from once. After lines have been added from it, to this work order or to a new one, no entry point offers the build action again: the completed inspection, the work order note and the asset row show the outcome instead, with a link to the work order that got the lines. The check is made again when Add Lines is pressed; if the inspection was built from elsewhere in the meantime, nothing is added and the user is told where the lines went | H14: Lines can be built from an inspection only once: instead of asking to confirm a second set, every place shows the result with a link to the work order that got the lines, and a late second Add Lines adds nothing and tells the user where the lines went. | I14: 29 Sep 2026 | J14: 29 Sep 2026: "QA contradiction pass answered" | K14: The change log entry names this rule | M14: Update the steps and expected results to match the new text. Vladimir: the automation for this case may check the old behaviour. | N14: =HYPERLINK("https://shopview.atlassian.net/wiki/pages/viewpage.action?pageId=768507905","Spec page")
A15: =HYPERLINK("https://shopview.testrail.io/index.php?/cases/view/88522","C88522") | B15: Building lines when the work order is deleted, built twice, or reopened | C15: Yes | D15: Viktoria (case text) and Vladimir (automation) | E15: S3-E1 | F15: If the work order the inspection was run on has been deleted, only the option to create a new work order is offered | G15: If the work order the inspection was run on has been deleted, no build action is offered (S5-E3). If it was built from before the deletion, the footer shows the outcome instead (S3-R8) | H15: When the inspection's work order has been deleted, no build action is offered at all (before, only 'a new work order' was offered); if lines were built before the deletion, the footer shows the result instead. | I15: 6 Oct 2026 | J15: 6 Oct 2026: "Deleted work orders, removed inspections and splits" Also: 7 Oct 2026: "Deleted work order after a build" | K15: The change log entry describes this change | M15: Update the steps and expected results to match the new text. Vladimir: the automation for this case may check the old behaviour. | N15: =HYPERLINK("https://shopview.atlassian.net/wiki/pages/viewpage.action?pageId=768507905","Spec page")
A16: =HYPERLINK("https://shopview.testrail.io/index.php?/cases/view/88522","C88522") | B16: Building lines when the work order is deleted, built twice, or reopened | C16: Yes | D16: Viktoria (case text) and Vladimir (automation) | E16: S3-E2 | F16: If another user builds from the same inspection while this screen is open, the confirmation in S2-R13 is based on the current state rather than the state when the screen loaded | G16: If another user builds from the same inspection while this screen is open, the check in S2-R13 is based on the current state rather than the state when the screen loaded | H16: Wording: when another user builds while the screen is open, the built-once check (not a confirmation) is based on the current state rather than the state when the screen loaded. | I16: 7 Oct 2026 | J16: 7 Oct 2026: "Leftovers from the built-once rule; file limit; submit name" | K16: The change log entry names this rule | M16: Update the steps and expected results to match the new text. Vladimir: the automation for this case may check the old behaviour. | N16: =HYPERLINK("https://shopview.atlassian.net/wiki/pages/viewpage.action?pageId=768507905","Spec page")
A17: =HYPERLINK("https://shopview.testrail.io/index.php?/cases/view/88524","C88524") | B17: Building again asks to confirm, based on the inspection as it is now | C17: No | D17: Viktoria (case text) | E17: S4-R3 | F17: The confirmation in S2-R13 will be based on the inspection's current state rather than on the note. The note reflects the inspection as it was when it completed, so a build performed elsewhere afterwards would otherwise go unnoticed and the same findings could be built twice without warning | G17: (removed from the spec) | H17: Removed: the rule that the 'add a second set?' confirmation is based on the inspection's current state, because lines can now be built from an inspection only once. | I17: 29 Sep 2026 | J17: 29 Sep 2026: "QA contradiction pass answered" | K17: The change log entry describes this change | M17: The spec no longer has this rule. Remove or rewrite the steps and expected results that check it. | N17: =HYPERLINK("https://shopview.atlassian.net/wiki/pages/viewpage.action?pageId=768507905","Spec page")
A18: =HYPERLINK("https://shopview.testrail.io/index.php?/cases/view/88524","C88524") | B18: Building again asks to confirm, based on the inspection as it is now | C18: No | D18: Viktoria (case text) | E18: S4-E2 | F18: If the inspection was already built from through another entry point, the user is asked to confirm | G18: (removed from the spec) | H18: Removed: building from the work order note after the inspection was already built from elsewhere no longer asks the user to confirm, because lines can now be built from an inspection only once. | I18: 29 Sep 2026 | J18: 29 Sep 2026: "QA contradiction pass answered" | K18: The change log entry describes this change | M18: The spec no longer has this rule. Remove or rewrite the steps and expected results that check it. | N18: =HYPERLINK("https://shopview.atlassian.net/wiki/pages/viewpage.action?pageId=768507905","Spec page")
A19: =HYPERLINK("https://shopview.testrail.io/index.php?/cases/view/88524","C88524") | B19: Building again asks to confirm, based on the inspection as it is now | C19: No | D19: Viktoria (case text) | E19: S2-R13 | F19: If lines have already been added from this inspection, the user will be asked to confirm before adding a second set. The check is made when Add Lines is pressed, on the state at that moment | G19: An inspection is built from once. After lines have been added from it, to this work order or to a new one, no entry point offers the build action again: the completed inspection, the work order note and the asset row show the outcome instead, with a link to the work order that got the lines. The check is made again when Add Lines is pressed; if the inspection was built from elsewhere in the meantime, nothing is added and the user is told where the lines went | H19: Lines can be built from an inspection only once: instead of asking to confirm a second set, every place shows the result with a link to the work order that got the lines, and a late second Add Lines adds nothing and tells the user where the lines went. | I19: 29 Sep 2026 | J19: 29 Sep 2026: "QA contradiction pass answered" | K19: The change log entry names this rule | M19: Update the steps and expected results to match the new text. | N19: =HYPERLINK("https://shopview.atlassian.net/wiki/pages/viewpage.action?pageId=768507905","Spec page")
A20: =HYPERLINK("https://shopview.testrail.io/index.php?/cases/view/88525","C88525") | B20: The note's Build lines is hidden until the inspection is ready | C20: Yes | D20: Viktoria (case text) and Vladimir (automation) | E20: S4-N2 | F20: If the inspection has been deleted, the note remains as a record but the action will not be shown | G20: If the inspection has been deleted, the note remains as a record but the action will not be shown. Removing an inspection from its line, or deleting the line, deletes the inspection on purpose: it leaves the asset's Inspections tab, and its note stays on the work order marked "Inspection deleted". This is different from deleting the whole work order (S5-E3) | H20: Adds that removing an inspection from its line, or deleting the line, deletes the inspection on purpose: it leaves the asset's Inspections tab and its note stays on the work order marked 'Inspection deleted'. | I20: 6 Oct 2026 | J20: 6 Oct 2026: "Deleted work orders, removed inspections and splits" | K20: The change log entry names this rule | M20: Update the steps and expected results to match the new text. Vladimir: the automation for this case may check the old behaviour. | N20: =HYPERLINK("https://shopview.atlassian.net/wiki/pages/viewpage.action?pageId=768507905","Spec page")
A21: =HYPERLINK("https://shopview.testrail.io/index.php?/cases/view/88527","C88527") | B21: Inspections tab columns: status, findings, work order, report and action | C21: Yes | D21: Viktoria (case text) and Vladimir (automation) | E21: S5-R9 | F21: The action column will have three states. Needs action offers the build described in S6. Done shows the outcome and links to the resulting work order, reading "WO created" when a new work order was created and "Lines added" when the lines went onto the existing one. Nothing to do shows a dash | G21: The action column will have three states. Needs action offers the build described in S6. Done shows the outcome and links to the resulting work order, reading "WO created" when a new work order was created and "Lines added" when the lines went onto the existing one. Nothing to do shows a dash. The same wording is used wherever the outcome replaces the build action (S2-R13) | H21: Adds that the same result wording ('WO created' / 'Lines added') is used everywhere the result replaces the build action. | I21: 29 Sep 2026 | J21: 29 Sep 2026: "QA contradiction pass answered" | K21: The change log entry describes this change | M21: Update the steps and expected results to match the new text. Vladimir: the automation for this case may check the old behaviour. | N21: =HYPERLINK("https://shopview.atlassian.net/wiki/pages/viewpage.action?pageId=768507905","Spec page")
A22: =HYPERLINK("https://shopview.testrail.io/index.php?/cases/view/88528","C88528") | B22: Inspections tab filters, summary line and needs-action counts | C22: Yes | D22: Viktoria (case text) and Vladimir (automation) | E22: S5-R10 | F22: A filter row will offer All, Needs action, With issues and Not started, each with a count taken from the full list rather than from the filtered view | G22: The table has no filter row. The Inspection, Status and Completed columns can be sorted. By default the most recently completed inspection comes first (S5-R2) | H22: The asset's Inspections tab no longer has a filter row (All, Needs action, With issues, Not started); instead the Inspection, Status and Completed columns can be sorted, with the most recently completed inspection first by default. | I22: 5 Oct 2026 | J22: 5 Oct 2026: "Developer and QA questions answered" Also: 29 Sep 2026: "QA contradiction pass answered"; 7 Oct 2026: "Filter leftovers removed" | K22: The change log entry describes this change | M22: Update the steps and expected results to match the new text. Vladimir: the automation for this case may check the old behaviour. | N22: =HYPERLINK("https://shopview.atlassian.net/wiki/pages/viewpage.action?pageId=768507905","Spec page")
A23: =HYPERLINK("https://shopview.testrail.io/index.php?/cases/view/88528","C88528") | B23: Inspections tab filters, summary line and needs-action counts | C23: Yes | D23: Viktoria (case text) and Vladimir (automation) | E23: S5-R11 | F23: A summary will read "N of M need a work order" | G23: A summary will read "N of M have findings with no lines yet" | H23: The summary line now reads 'N of M have findings with no lines yet' instead of 'N of M need a work order'. | I23: between 29 Sep 2026 and 2 Oct 2026 | K23: Not named in the change log; Jira SV-10792 (2 Oct 2026) already quotes the new text | M23: Update the steps and expected results to match the new text. Vladimir: the automation for this case may check the old behaviour. | N23: =HYPERLINK("https://shopview.atlassian.net/wiki/pages/viewpage.action?pageId=768507905","Spec page")
A24: =HYPERLINK("https://shopview.testrail.io/index.php?/cases/view/88528","C88528") | B24: Inspections tab filters, summary line and needs-action counts | C24: Yes | D24: Viktoria (case text) and Vladimir (automation) | E24: S5-R12 | F24: An inspection needs action when it was completed after this release, has at least one Monitor or Not OK finding, and has not been built from. An inspection completed before the release is never flagged, because the data cannot tell one somebody already handled by hand from one nobody actioned. Those stay reachable through the With issues filter | G24: An inspection needs action when it was completed after this release, has at least one Monitor or Not OK finding, and has not been built from. An inspection completed before the release is never flagged, because the data cannot tell one somebody already handled by hand from one nobody actioned. Those stay listed on the tab, with their issues shown | H24: Inspections completed before the release now stay listed on the tab with their issues shown, instead of being reachable through the With issues filter. | I24: 7 Oct 2026 | J24: 7 Oct 2026: "Filter leftovers removed" | K24: The change log entry describes this change | M24: Update the steps and expected results to match the new text. Vladimir: the automation for this case may check the old behaviour. | N24: =HYPERLINK("https://shopview.atlassian.net/wiki/pages/viewpage.action?pageId=768507905","Spec page")
A25: =HYPERLINK("https://shopview.testrail.io/index.php?/cases/view/88529","C88529") | B25: Inspections tab links and buttons, phone use, and the inspection's asset | C25: Yes | D25: Viktoria (case text) and Vladimir (automation) | E25: S5-R16 | F25: The filter row will wrap on a phone rather than scrolling out of view, and will keep its counts | G25: (removed from the spec) | H25: Removed: the phone rule that the filter row on the asset's Inspections tab wraps and keeps its counts, because the tab no longer has a filter row. | I25: 29 Sep 2026 | J25: 29 Sep 2026: "QA contradiction pass answered" Also: 7 Oct 2026: "Filter leftovers removed" | K25: The change log entry describes this change | M25: The spec no longer has this rule. Remove or rewrite the steps and expected results that check it. Vladimir: the automation for this case may check the old behaviour. | N25: =HYPERLINK("https://shopview.atlassian.net/wiki/pages/viewpage.action?pageId=768507905","Spec page")
A26: =HYPERLINK("https://shopview.testrail.io/index.php?/cases/view/88529","C88529") | B26: Inspections tab links and buttons, phone use, and the inspection's asset | C26: Yes | D26: Viktoria (case text) and Vladimir (automation) | E26: S5-R21 | F26: An inspection records the asset it was run on, stored on the inspection when it is created rather than derived through its work order. A work order carries exactly one asset and that asset can be changed later, so this tab is a record of what was inspected rather than a view that follows a later correction. Inspections that exist before this release are backfilled from their work order’s asset at migration, without which this tab cannot show history | G26: The tab lists the inspections whose work order is on this asset now, so it follows the work order when the work order's asset is changed or two assets are merged. The asset an inspection was run on is also stored on the inspection when it is created, as a record. Inspections that exist before this release are backfilled from their work order's asset at migration. When the work order has been deleted, the stored asset is used (S5-E3). Merging assets moves such inspections to the surviving asset, as it moves the work orders | H26: The asset's Inspections tab now lists the inspections whose work order is on this asset now, so it follows the work order when its asset is changed or assets are merged; the asset stored on the inspection is kept as a record and used when the work order has been deleted, and merging assets moves such inspections to the surviving asset. | I26: 5 Oct 2026 | J26: 5 Oct 2026: "Developer and QA questions answered" Also: 7 Oct 2026: "Deleted work order: outcome, footer, reopened, merge (SV-10965)" | K26: The change log entry describes this change | L26: =HYPERLINK("https://shopview.atlassian.net/browse/SV-10965","SV-10965") | M26: Update the steps and expected results to match the new text. Vladimir: the automation for this case may check the old behaviour. | N26: =HYPERLINK("https://shopview.atlassian.net/wiki/pages/viewpage.action?pageId=768507905","Spec page")
A27: =HYPERLINK("https://shopview.testrail.io/index.php?/cases/view/88530","C88530") | B27: How findings are counted, once per axle | C27: No | D27: Viktoria (case text) | E27: S5-R17 | F27: A response contributes one count to exactly one of Pass, Monitor or Needs attention when the field is visible, the field is a checkbox or a measurement, and the response is Pass, Monitor or Not OK | G27: A response contributes one count to exactly one of Pass, Monitor or Needs attention when the field is a checkbox or a measurement and the response is Pass, Monitor or Not OK | H27: The counting rule no longer says the field must be visible: a checkbox or measurement answer of Pass, Monitor or Not OK counts once. | I27: between 29 Sep 2026 and 13 Oct 2026 | K27: Not named in the change log; changed between 29 Sep and 13 Oct | M27: Update the steps and expected results to match the new text. | N27: =HYPERLINK("https://shopview.atlassian.net/wiki/pages/viewpage.action?pageId=768507905","Spec page")
A28: =HYPERLINK("https://shopview.testrail.io/index.php?/cases/view/88530","C88530") | B28: How findings are counted, once per axle | C28: No | D28: Viktoria (case text) | E28: S5-R20 | F28: A per-axle measurement field contributes one count per axle, because each axle is a separate inspected position. A field with three axles marked OK, Monitor and Not OK contributes one pass, one monitor and one needs-attention | G28: A per-axle measurement field contributes one count per axle, carrying that axle's worst verdict (S8-R14). A field with three axles marked OK, Monitor and Not OK contributes one pass, one monitor and one needs-attention | H28: Adds that each axle's single count carries that axle's worst verdict. | I28: between 29 Sep 2026 and 13 Oct 2026 | K28: Not named in the change log; changed between 29 Sep and 13 Oct | M28: Update the steps and expected results to match the new text. | N28: =HYPERLINK("https://shopview.atlassian.net/wiki/pages/viewpage.action?pageId=768507905","Spec page")
A29: =HYPERLINK("https://shopview.testrail.io/index.php?/cases/view/88532","C88532") | B29: Inspections tab with not-started, all N/A, deleted, moved and many inspections | C29: Yes | D29: Viktoria (case text) and Vladimir (automation) | E29: S5-E3 | F29: If the work order the inspection was run on has been deleted, the inspection remains listed, the work order column shows a dash rather than a broken link, and the row remains usable. This requires an inspection to outlive its work order rather than being removed with it | G29: If the work order the inspection was run on is deleted, an inspection that has a report stays on the asset's Inspections tab as a read-only record, with a dash in the Work order column. The Action column shows the outcome only while the work order it points to exists, for example 'WO created S-200' when the lines went onto another work order; when they went onto the deleted work order itself, it shows a dash. It can be opened and its latest report downloaded. It cannot be built from, reopened or regenerated. A reopened inspection survives as its latest report: Status reads Completed, Completed shows the date of that report, and opening the row opens that report rather than the answers, which may have changed since. Deleting a work order must not delete such an inspection, its photos or its report. An inspection with no report, including one that was submitted but whose report was never generated, is deleted with its work order | H29: When the work order is deleted, only an inspection with a report stays on the tab, read-only, with a dash for the work order; the Action column shows the result only while the work order it points to exists; it can be opened and its latest report downloaded but not built from, reopened or regenerated; a reopened one shows as Completed on its latest report's date and opens that report; an inspection with no report is deleted with the work order. | I29: 6 Oct 2026 | J29: 6 Oct 2026: "Deleted work orders, removed inspections and splits" Also: 7 Oct 2026: "Deleted work order after a build"; 7 Oct 2026: "Deleted work order: outcome, footer, reopened, merge (SV-10965)" | K29: The change log entry describes this change | L29: =HYPERLINK("https://shopview.atlassian.net/browse/SV-10965","SV-10965") | M29: Update the steps and expected results to match the new text. Vladimir: the automation for this case may check the old behaviour. | N29: =HYPERLINK("https://shopview.atlassian.net/wiki/pages/viewpage.action?pageId=768507905","Spec page")
A30: =HYPERLINK("https://shopview.testrail.io/index.php?/cases/view/88533","C88533") | B30: Build lines from a needs-action row, with the same work order choice | C30: Yes | D30: Viktoria (case text) and Vladimir (automation) | E30: S2-R15 | F30: A destination that cannot take lines will keep its place in the menu and say why. A destination that silently stops being offered reads as a fault | G30: (removed from the spec) | H30: Removed: a destination that cannot take lines no longer stays in the menu with a reason; it is simply not shown. | I30: 29 Sep 2026 | J30: 29 Sep 2026: "QA contradiction pass answered" | K30: The change log entry describes this change | M30: The spec no longer has this rule. Remove or rewrite the steps and expected results that check it. Vladimir: the automation for this case may check the old behaviour. | N30: =HYPERLINK("https://shopview.atlassian.net/wiki/pages/viewpage.action?pageId=768507905","Spec page")
A31: =HYPERLINK("https://shopview.testrail.io/index.php?/cases/view/88533","C88533") | B31: Build lines from a needs-action row, with the same work order choice | C31: Yes | D31: Viktoria (case text) and Vladimir (automation) | E31: S2-R5 | F31: When the work order the inspection was run on is not an eligible build target, the system will create a new work order without asking. It is ineligible when its status is Complete, Invoiced, Paid or Declined, or when an invoice already exists. Declined counts as ineligible because lines added to a refused order would revive work the customer turned down | G31: When the work order the inspection was run on is not an eligible build target, the destination menu still opens and offers only a new work order. It is ineligible when its status is Complete, Invoiced, Paid or Declined, or when an invoice already exists. Declined counts as ineligible because lines added to a refused order would revive work the customer turned down | H31: When the inspection's own work order cannot take lines, the destination menu still opens and offers only a new work order, instead of a new work order being created without asking. | I31: 29 Sep 2026 | J31: 29 Sep 2026: "QA contradiction pass answered" | K31: The change log entry describes this change | M31: Update the steps and expected results to match the new text. Vladimir: the automation for this case may check the old behaviour. | N31: =HYPERLINK("https://shopview.atlassian.net/wiki/pages/viewpage.action?pageId=768507905","Spec page")
A32: =HYPERLINK("https://shopview.testrail.io/index.php?/cases/view/88533","C88533") | B32: Build lines from a needs-action row, with the same work order choice | C32: Yes | D32: Viktoria (case text) and Vladimir (automation) | E32: S6-R4 | F32: The inspection's own work order is offered as a target only while it is an eligible build target, judged by its status on the row. When it is not, the target keeps its place and says why (S2-R15) | G32: The inspection's own work order is offered as a target only while it is an eligible build target, judged by its status on the row. When it is not, it is not offered (S2-R5) | H32: When the inspection's own work order cannot take lines, it is now left out of the menu instead of staying there with a reason. | I32: 29 Sep 2026 | J32: 29 Sep 2026: "QA contradiction pass answered" | K32: The change log entry describes this change | M32: Update the steps and expected results to match the new text. Vladimir: the automation for this case may check the old behaviour. | N32: =HYPERLINK("https://shopview.atlassian.net/wiki/pages/viewpage.action?pageId=768507905","Spec page")
A33: =HYPERLINK("https://shopview.testrail.io/index.php?/cases/view/88534","C88534") | B33: After building, the row shows the result and the counts update | C33: No | D33: Viktoria (case text) | E33: S6-R7 | F33: After a successful build, the row will leave the Needs action filter and the counts and summary will update with it | G33: After a successful build, the row will show its outcome instead of the action, and the counts and the summary line will update with it | H33: After a build, the row now shows its result in place of the build action (instead of leaving the Needs action filter), and the counts and the summary line update. | I33: 7 Oct 2026 | J33: 7 Oct 2026: "Filter leftovers removed" | K33: The change log entry describes this change | M33: Update the steps and expected results to match the new text. | N33: =HYPERLINK("https://shopview.atlassian.net/wiki/pages/viewpage.action?pageId=768507905","Spec page")
A34: =HYPERLINK("https://shopview.testrail.io/index.php?/cases/view/88536","C88536") | B34: Row build with a deleted work order, per row, or a row you can't start | C34: Yes | D34: Viktoria (case text) and Vladimir (automation) | E34: S6-E1 | F34: If the work order the inspection was run on has been deleted, only the new-work-order target is offered | G34: If the work order the inspection was run on has been deleted, the row offers no build action and its action cell shows a dash, or the outcome if it was built from before the deletion (S5-E3) | H34: When the inspection's work order has been deleted, the row offers no build action and shows a dash, or the result if it was built from before the deletion (before, only the new work order target was offered). | I34: 6 Oct 2026 | J34: 6 Oct 2026: "Deleted work orders, removed inspections and splits" Also: 7 Oct 2026: "Deleted work order after a build" | K34: The change log entry describes this change | M34: Update the steps and expected results to match the new text. Vladimir: the automation for this case may check the old behaviour. | N34: =HYPERLINK("https://shopview.atlassian.net/wiki/pages/viewpage.action?pageId=768507905","Spec page")
A35: =HYPERLINK("https://shopview.testrail.io/index.php?/cases/view/88536","C88536") | B35: Row build with a deleted work order, per row, or a row you can't start | C35: Yes | D35: Viktoria (case text) and Vladimir (automation) | E35: S6-E3 | F35: A user who can fill inspections but cannot create work orders, looking at a row whose work order is closed, has no available action. The row will show a dash with an explanation that creating a work order requires 'Work Orders — Create & Edit'. The explanation must be readable on a phone, where there is no hover | G35: A user who can fill inspections but cannot create work orders, looking at a row whose work order is closed, has no available action. The row shows a dash | H35: For a user who can fill inspections but cannot create work orders, a row whose work order is closed now just shows a dash; the explanation about the 'Work Orders — Create & Edit' permission (readable on a phone) is dropped. | I35: between 29 Sep 2026 and 13 Oct 2026 | K35: Not named in the change log; changed between 29 Sep and 13 Oct | M35: Update the steps and expected results to match the new text. Vladimir: the automation for this case may check the old behaviour. | N35: =HYPERLINK("https://shopview.atlassian.net/wiki/pages/viewpage.action?pageId=768507905","Spec page")
A36: =HYPERLINK("https://shopview.testrail.io/index.php?/cases/view/88537","C88537") | B36: A work order note says its lines were built from an inspection | C36: Yes | D36: Viktoria (case text) and Vladimir (automation) | E36: S7-R2 | F36: When the lines went onto a new work order, the note will link back to the work order the inspection was run on | G36: When the lines went onto a new work order, the note will link back to the work order the inspection was run on. If that work order was deleted after the build, the note shows its number as text, tagged 'Work order deleted', with no link | H36: Adds that if the original work order was deleted after the build, the note shows its number as plain text tagged 'Work order deleted', with no link. | I36: 7 Oct 2026 | J36: 7 Oct 2026: "Deleted work order after a build" | K36: The change log entry describes this change | M36: Update the steps and expected results to match the new text. Vladimir: the automation for this case may check the old behaviour. | N36: =HYPERLINK("https://shopview.atlassian.net/wiki/pages/viewpage.action?pageId=768507905","Spec page")
A37: =HYPERLINK("https://shopview.testrail.io/index.php?/cases/view/88538","C88538") | B37: The Audit Log records each build, wherever it was started | C37: Yes | D37: Viktoria (case text) and Vladimir (automation) | E37: S7-R5 | F37: The Audit Log entry will name the inspection, link to it, and name the work order the inspection was run on | G37: The Audit Log entry will name the inspection, link to it, and name the work order the inspection was run on. If that work order was deleted after the build, its number is shown as text, with no link | H37: Adds that if the original work order was deleted after the build, the Audit Log entry shows its number as plain text, with no link. | I37: 7 Oct 2026 | J37: 7 Oct 2026: "Deleted work order after a build" | K37: The change log entry describes this change | M37: Update the steps and expected results to match the new text. Vladimir: the automation for this case may check the old behaviour. | N37: =HYPERLINK("https://shopview.atlassian.net/wiki/pages/viewpage.action?pageId=768507905","Spec page")
A38: =HYPERLINK("https://shopview.testrail.io/index.php?/cases/view/88539","C88539") | B38: The work order note and Audit Log match, including the line count | C38: Yes | D38: Viktoria (case text) and Vladimir (automation) | E38: S7-R7 | F38: The Audit Log entry and the note will carry the same three facts: that the work order was built from an inspection, which inspection, and which work order the inspection was run on. Whichever a user opens, they get the same account. Neither may carry a fact the other lacks | G38: The Audit Log entry and the note will carry the same three facts: that the work order was built from an inspection, which inspection, and which work order the inspection was run on. Whichever a user opens, they get the same account. Neither may carry a fact the other lacks. This holds when both records exist. If one could not be written (S7-E1), the other stands alone and the failure is logged; the user is not told | H38: Adds that the note and the Audit Log entry must match only when both exist; if one could not be written, the other stands alone, the failure is logged and the user is not told. | I38: between 29 Sep 2026 and 13 Oct 2026 | K38: Not named in the change log; changed between 29 Sep and 13 Oct | M38: Update the steps and expected results to match the new text. Vladimir: the automation for this case may check the old behaviour. | N38: =HYPERLINK("https://shopview.atlassian.net/wiki/pages/viewpage.action?pageId=768507905","Spec page")
A39: =HYPERLINK("https://shopview.testrail.io/index.php?/cases/view/88539","C88539") | B39: The work order note and Audit Log match, including the line count | C39: Yes | D39: Viktoria (case text) and Vladimir (automation) | E39: S7-R8 | F39: Both records will state how many lines were created, and the asset row will read "3 lines added" rather than "Lines added". The count is known when the record is written, and the scale of what was added is the first thing an advisor wants from it | G39: Both records will state how many lines were created. The count is known when the record is written, and the scale of what was added is the first thing an advisor wants from it | H39: The asset row no longer reads '3 lines added' instead of 'Lines added'; the note and the Audit Log entry still state how many lines were created. | I39: between 29 Sep 2026 and 13 Oct 2026 | K39: Not named in the change log; changed between 29 Sep and 13 Oct | M39: Update the steps and expected results to match the new text. Vladimir: the automation for this case may check the old behaviour. | N39: =HYPERLINK("https://shopview.atlassian.net/wiki/pages/viewpage.action?pageId=768507905","Spec page")
A40: =HYPERLINK("https://shopview.testrail.io/index.php?/cases/view/88540","C88540") | B40: Lines are kept if the note or Audit Log fails, deleted records handled | C40: Yes | D40: Viktoria (case text) and Vladimir (automation) | E40: S7-E4 | F40: If the work order is later split, the note and the Audit Log entry stay on the original. The new work order carries no inspection provenance, because a split moves lines and does not copy records | G40: If the work order is later split, the note and the Audit Log entry stay on the original. The new work order carries no inspection provenance, because a split moves lines and does not copy records. The inspection's report notes are not records of the build: when a line with an inspection is split onto a new work order, those notes move with the line and are removed from the original. Work orders split before this rule keep their notes where they are | H40: Adds that when a line with an inspection is split onto a new work order, the inspection's report notes move with the line and are removed from the original; work orders split before this rule keep their notes where they are. | I40: 6 Oct 2026 | J40: 6 Oct 2026: "Deleted work orders, removed inspections and splits" | K40: The change log entry names this rule | L40: =HYPERLINK("https://shopview.atlassian.net/browse/SV-10913","SV-10913") | M40: Update the steps and expected results to match the new text. Vladimir: the automation for this case may check the old behaviour. | N40: =HYPERLINK("https://shopview.atlassian.net/wiki/pages/viewpage.action?pageId=768507905","Spec page")
...

Sheet Later Jira decisions
A1: Case | B1: Case title | C1: Automated? | D1: Ticket | E1: Who decided, and when | F1: The decision | G1: What the spec still says | H1: What to do
A2: =HYPERLINK("https://shopview.testrail.io/index.php?/cases/view/88575","C88575") | B2: The customer report stays correct when regenerated or republished | C2: No | D2: =HYPERLINK("https://shopview.atlassian.net/browse/SV-10960","SV-10960") | E2: Milos Vasic (product), 8 Oct 2026 | F2: When a work order is deleted, the inspection that survives moves to the asset the work order has at that moment. Changing or merging an asset never regenerates existing reports; a manual regenerate uses the work order's current asset. | G2: The tab lists the inspections whose work order is on this asset now, so it follows the work order when the work order's asset is changed or two assets are merged. The asset an inspection was run on is also stored on the inspection when it is created, as a record. Inspections that exist before this release are backfilled from their work order's asset at migration. When the work order has been deleted, the stored asset is used (S5-E3). Merging assets moves such inspections to the surviving asset, as it moves the work orders | H2: The decision is later than the spec, so the latest decision wins. Add it to the case.
A3: =HYPERLINK("https://shopview.testrail.io/index.php?/cases/view/88561","C88561") | B3: A failed upload, replacing a file, long names and a missing file | C3: No | D3: =HYPERLINK("https://shopview.atlassian.net/browse/SV-11103","SV-11103") | E3: Branko Cicovic (design), 12 Oct 2026 | F3: Long names end with "…" and show the full name in a tooltip on hover. | G3: The spec only says long names are shortened. | H3: The decision is later than the spec, so the latest decision wins. Add it to the case.
A4: =HYPERLINK("https://shopview.testrail.io/index.php?/cases/view/88579","C88579") | B4: On a phone: scrolling, overlapping items, many axles and long names | C4: No | D4: =HYPERLINK("https://shopview.atlassian.net/browse/SV-11103","SV-11103") | E4: Branko Cicovic (design), 12 Oct 2026 | F4: Long names end with "…" and show the full name in a tooltip on hover. | G4: The spec only says long names are shortened. | H4: The decision is later than the spec, so the latest decision wins. Add it to the case.

Sheet No case yet
A1: Spec rule or ticket | B1: What it says | C1: When it was added or decided | D1: Source | E1: What to do
A2: S13-R14 | B2: The inspected date is the date the inspection was first completed. Regenerating a report does not move it; reopening the inspection and completing it again gives it a new date, which is how a newer version is told apart | C2: 5 Oct 2026 (5 Oct 2026: "Developer and QA questions answered") | D2: =HYPERLINK("https://shopview.atlassian.net/wiki/pages/viewpage.action?pageId=768507905","Spec page") | E2: New rule with no case. Add a case if it should be tested.
A3: S13-R15 | B3: Regenerating a report does not post another note on the work order. The existing note keeps pointing at the most recent version (S13-R12) | C3: 5 Oct 2026 (5 Oct 2026: "Developer and QA questions answered") | D3: =HYPERLINK("https://shopview.atlassian.net/wiki/pages/viewpage.action?pageId=768507905","Spec page") | E3: New rule with no case. Add a case if it should be tested.
A4: S15-E7 | B4: When the target is a new work order, it is created as soon as it is chosen (S2-R11). If the drafting is cancelled, fails, returns nothing, or the user leaves, that work order stays, empty. Nothing is deleted automatically. The inspection stays Needs action, no provenance note is written, and a retry runs on the same work order | C4: between 29 Sep 2026 and 2 Oct 2026 | D4: =HYPERLINK("https://shopview.atlassian.net/wiki/pages/viewpage.action?pageId=768507905","Spec page") | E4: New rule with no case. Add a case if it should be tested.
A5: S15-N6 | B5: Photos are not sent to ShopCoach; the technician's note is the only evidence it reads | C5: between 29 Sep 2026 and 13 Oct 2026 | D5: =HYPERLINK("https://shopview.atlassian.net/wiki/pages/viewpage.action?pageId=768507905","Spec page") | E5: New rule with no case. Add a case if it should be tested.
A6: S3-R8 | B6: Once the inspection has been built from, the footer shows the outcome in place of Build lines: 'WO created S-235' or 'Lines added S-58', linking to that work order (S2-R13) | C6: 29 Sep 2026 (29 Sep 2026: "QA contradiction pass answered") | D6: =HYPERLINK("https://shopview.atlassian.net/wiki/pages/viewpage.action?pageId=768507905","Spec page") | E6: New rule with no case. Add a case if it should be tested.
A7: S4-R5 | B7: Once the inspection has been built from, the note shows the outcome in place of Build lines, worded as in S3-R8 (S2-R13) | C7: 29 Sep 2026 (29 Sep 2026: "QA contradiction pass answered") | D7: =HYPERLINK("https://shopview.atlassian.net/wiki/pages/viewpage.action?pageId=768507905","Spec page") | E7: New rule with no case. Add a case if it should be tested.
A8: =HYPERLINK("https://shopview.atlassian.net/browse/SV-10938","SV-10938") | B8: On a phone, filling an inspection has Save & exit, like desktop. (Not in the spec yet.) | C8: 9 Oct 2026, Milos Vasic | D8: =HYPERLINK("https://shopview.atlassian.net/browse/SV-10938","Jira") | E8: Add a case if it should be tested.
