Workbook

Sheet Summary
A1: Global Search V2 — automated test results
A3: Environment | B3: Staging
A4: Build tested | B4: v26.40.3-36ebbb0
A5: Run date | B5: 2 October 2026 (full run); fixed tests re-run 2–3 October 2026, same build
A6: How it was run | B6: npm test from a fresh copy of the branch: the data was seeded and checked first, then every spec ran. Failures caused by the tests themselves were then fixed and those test files re-run on the same build.
A7: Recorded in TestRail? | B7: No — by instruction, this run is reported only in this file.
A8: Test run these cases belong to | B8: Run 415
A10: Result | B10: Tests | C10: What it means
A11: Passed | B11: =COUNTIF('All results'!$E:$E,A11) -> 218 | C11: The product did what the requirement says.
A12: Failed — possible new problem | B12: =COUNTIF('All results'!$E:$E,A12) -> 7 | C12: The product did not, and no ticket describes it. Not yet checked against the requirement; nothing raised.
A13: Failed — already reported | B13: =COUNTIF('All results'!$E:$E,A13) -> 9 | C13: The product did not, in a way a filed ticket already describes. Nothing new.
A14: Failed — our test's fault | B14: =COUNTIF('All results'!$E:$E,A14) -> 18 | C14: The test was at fault, not the product. Fixed; see the re-run result on each row.
A15: Known fault — still there | B15: =COUNTIF('All results'!$E:$E,A15) -> 21 | C15: A fault already in a ticket is still present. Expected.
A16: Known fault — did not reproduce | B16: =COUNTIF('All results'!$E:$E,A16) -> 1 | C16: A known fault did not happen this time — possibly fixed. Worth checking by hand.
A17: Stood down | B17: =COUNTIF('All results'!$E:$E,A17) -> 64 | C17: Not judged: something the test needs was missing. The reason is on each row.
A18: Total | B18: =SUM(B11:B17) -> 338 | C18: Should equal the number of tests in the suite (338).
A19: Of the test's-fault failures: passed when re-run after the fix | B19: =COUNTIFS('All results'!$E:$E,"Failed — our test's fault",'All results'!$N:$N,"Passed") -> 18 | C19: Each was a fault in the test, not the product, and has been fixed. Should equal the line above it in the table.
A21: Failures by what happened | B21: Tests
A22: A contact's e-mail match shows a different detail of the record instead of the e-mail. | B22: =COUNTIF('All results'!$F:$F,A22) -> 0
A23: None of the 65 rows for the typed text carried a highlight. | B23: =COUNTIF('All results'!$F:$F,A23) -> 0
A24: Parts: the whole part name is highlighted, instead of just the typed part inside it. | B24: =COUNTIF('All results'!$F:$F,A24) -> 0
A25: Purchase orders: a received order is listed above one still on order. | B25: =COUNTIF('All results'!$F:$F,A25) -> 0
A26: The customer row does not show the telephone on hover. | B26: =COUNTIF('All results'!$F:$F,A26) -> 0
A27: The row shows only the characters typed, not the whole value that matched. | B27: =COUNTIF('All results'!$F:$F,A27) -> 0
A28: The search box did not open in time, in the file whose other tests had just failed on the wrong server. | B28: =COUNTIF('All results'!$F:$F,A28) -> 0
A29: The search box did not respond to a click within 60 seconds — test timing, not a product behaviour. | B29: =COUNTIF('All results'!$F:$F,A29) -> 0
A30: The test failed on a row that matched on a detail it does not display, which cannot show where a highlight sits. | B30: =COUNTIF('All results'!$F:$F,A30) -> 0
A31: The test looked for a technician by a first name that exists only on the old QA branch, so it never switched person and measured what an administrator sees. | B31: =COUNTIF('All results'!$F:$F,A31) -> 0
A32: The test looked for the two suppliers it had just created in a list that did not include them, and crashed. | B32: =COUNTIF('All results'!$F:$F,A32) -> 0
A33: The test sent its requests to the production server instead of staging (a server address written into one helper). | B33: =COUNTIF('All results'!$F:$F,A33) -> 0
... A36: Vehicles: two different vehicles (same unit number, different serial number) read identically in the results. | B36: =COUNTIF('All results'!$F:$F,A36) -> 0
A39: Spec file | B39: Passed | C39: Possible new | D39: Already reported | E39: Our test | F39: Known still there | G39: Known gone | H39: Stood down
A40: C146197-C146208-sri-work-orders.spec.ts | B40: =COUNTIFS('All results'!$K:$K,$A40,'All results'!$E:$E,"Passed") -> 6 | C40: =COUNTIFS('All results'!$K:$K,$A40,'All results'!$E:$E,"Failed — possible new problem") -> 0 | D40: =COUNTIFS('All results'!$K:$K,$A40,'All results'!$E:$E,"Failed — already reported") -> 0 | E40: =COUNTIFS('All results'!$K:$K,$A40,'All results'!$E:$E,"Failed — our test's fault") -> 0 | F40: =COUNTIFS('All results'!$K:$K,$A40,'All results'!$E:$E,"Known fault — still there") -> 0 | G40: =COUNTIFS('All results'!$K:$K,$A40,'All results'!$E:$E,"Known fault — did not reproduce") -> 0 | H40: =COUNTIFS('All results'!$K:$K,$A40,'All results'!$E:$E,"Stood down") -> 1
A41: C146202-C146282-sri-retest-full-value.spec.ts | B41: =COUNTIFS('All results'!$K:$K,$A41,'All results'!$E:$E,"Passed") -> 5 | C41: =COUNTIFS('All results'!$K:$K,$A41,'All results'!$E:$E,"Failed — possible new problem") -> 1 | D41: =COUNTIFS('All results'!$K:$K,$A41,'All results'!$E:$E,"Failed — already reported") -> 7 | E41: =COUNTIFS('All results'!$K:$K,$A41,'All results'!$E:$E,"Failed — our test's fault") -> 0 | F41: =COUNTIFS('All results'!$K:$K,$A41,'All results'!$E:$E,"Known fault — still there") -> 15 | G41: =COUNTIFS('All results'!$K:$K,$A41,'All results'!$E:$E,"Known fault — did not reproduce") -> 0 | H41: =COUNTIFS('All results'!$K:$K,$A41,'All results'!$E:$E,"Stood down") -> 0
A42: C146209-C146223-sri-customers.spec.ts | B42: =COUNTIFS('All results'!$K:$K,$A42,'All results'!$E:$E,"Passed") -> 3 | C42: =COUNTIFS('All results'!$K:$K,$A42,'All results'!$E:$E,"Failed — possible new problem") -> 0 | D42: =COUNTIFS('All results'!$K:$K,$A42,'All results'!$E:$E,"Failed — already reported") -> 2 | E42: =COUNTIFS('All results'!$K:$K,$A42,'All results'!$E:$E,"Failed — our test's fault") -> 0 | F42: =COUNTIFS('All results'!$K:$K,$A42,'All results'!$E:$E,"Known fault — still there") -> 0 | G42: =COUNTIFS('All results'!$K:$K,$A42,'All results'!$E:$E,"Known fault — did not reproduce") -> 0 | H42: =COUNTIFS('All results'!$K:$K,$A42,'All results'!$E:$E,"Stood down") -> 1
A43: C146224-C146284-sri-entities.spec.ts | B43: =COUNTIFS('All results'!$K:$K,$A43,'All results'!$E:$E,"Passed") -> 28 | C43: =COUNTIFS('All results'!$K:$K,$A43,'All results'!$E:$E,"Failed — possible new problem") -> 4 | D43: =COUNTIFS('All results'!$K:$K,$A43,'All results'!$E:$E,"Failed — already reported") -> 0 | E43: =COUNTIFS('All results'!$K:$K,$A43,'All results'!$E:$E,"Failed — our test's fault") -> 4 | F43: =COUNTIFS('All results'!$K:$K,$A43,'All results'!$E:$E,"Known fault — still there") -> 0 | G43: =COUNTIFS('All results'!$K:$K,$A43,'All results'!$E:$E,"Known fault — did not reproduce") -> 0 | H43: =COUNTIFS('All results'!$K:$K,$A43,'All results'!$E:$E,"Stood down") -> 6
A44: C146285-C146306-sri-all-tab.spec.ts | B44: =COUNTIFS('All results'!$K:$K,$A44,'All results'!$E:$E,"Passed") -> 19 | C44: =COUNTIFS('All results'!$K:$K,$A44,'All results'!$E:$E,"Failed — possible new problem") -> 0 | D44: =COUNTIFS('All results'!$K:$K,$A44,'All results'!$E:$E,"Failed — already reported") -> 0 | E44: =COUNTIFS('All results'!$K:$K,$A44,'All results'!$E:$E,"Failed — our test's fault") -> 1 | F44: =COUNTIFS('All results'!$K:$K,$A44,'All results'!$E:$E,"Known fault — still there") -> 0 | G44: =COUNTIFS('All results'!$K:$K,$A44,'All results'!$E:$E,"Known fault — did not reproduce") -> 1 | H44: =COUNTIFS('All results'!$K:$K,$A44,'All results'!$E:$E,"Stood down") -> 1
A45: C44804-C55683-panel-keyboard.spec.ts | B45: =COUNTIFS('All results'!$K:$K,$A45,'All results'!$E:$E,"Passed") -> 10 | C45: =COUNTIFS('All results'!$K:$K,$A45,'All results'!$E:$E,"Failed — possible new problem") -> 0 | D45: =COUNTIFS('All results'!$K:$K,$A45,'All results'!$E:$E,"Failed — already reported") -> 0 | E45: =COUNTIFS('All results'!$K:$K,$A45,'All results'!$E:$E,"Failed — our test's fault") -> 1 | F45: =COUNTIFS('All results'!$K:$K,$A45,'All results'!$E:$E,"Known fault — still there") -> 0 | G45: =COUNTIFS('All results'!$K:$K,$A45,'All results'!$E:$E,"Known fault — did not reproduce") -> 0 | H45: =COUNTIFS('All results'!$K:$K,$A45,'All results'!$E:$E,"Stood down") -> 0
A46: access-and-location.spec.ts | B46: =COUNTIFS('All results'!$K:$K,$A46,'All results'!$E:$E,"Passed") -> 1 | C46: =COUNTIFS('All results'!$K:$K,$A46,'All results'!$E:$E,"Failed — possible new problem") -> 0 | D46: =COUNTIFS('All results'!$K:$K,$A46,'All results'!$E:$E,"Failed — already reported") -> 0 | E46: =COUNTIFS('All results'!$K:$K,$A46,'All results'!$E:$E,"Failed — our test's fault") -> 5 | F46: =COUNTIFS('All results'!$K:$K,$A46,'All results'!$E:$E,"Known fault — still there") -> 0 | G46: =COUNTIFS('All results'!$K:$K,$A46,'All results'!$E:$E,"Known fault — did not reproduce") -> 0 | H46: =COUNTIFS('All results'!$K:$K,$A46,'All results'!$E:$E,"Stood down") -> 0
A47: counts-and-ranking.spec.ts | B47: =COUNTIFS('All results'!$K:$K,$A47,'All results'!$E:$E,"Passed") -> 0 | C47: =COUNTIFS('All results'!$K:$K,$A47,'All results'!$E:$E,"Failed — possible new problem") -> 1 | D47: =COUNTIFS('All results'!$K:$K,$A47,'All results'!$E:$E,"Failed — already reported") -> 0 | E47: =COUNTIFS('All results'!$K:$K,$A47,'All results'!$E:$E,"Failed — our test's fault") -> 1 | F47: =COUNTIFS('All results'!$K:$K,$A47,'All results'!$E:$E,"Known fault — still there") -> 2 | G47: =COUNTIFS('All results'!$K:$K,$A47,'All results'!$E:$E,"Known fault — did not reproduce") -> 0 | H47: =COUNTIFS('All results'!$K:$K,$A47,'All results'!$E:$E,"Stood down") -> 1
...

Sheet All results
A1: Every test in this run, one row each. The Summary counts are formulas over this sheet.
A2: Case | B2: Case in TestRail | C2: Test run | D2: What the test checks | E2: Result | F2: Likely cause | G2: What happened | H2: What needs to be done | I2: Ticket | J2: Ticket status (read live) | K2: Spec file | L2: Line | M2: Seconds | N2: Re-run after fixing the test | O2: Re-run detail
A3: C146216 | B3: Open case | C3: Run 415 | D3: C146216 — SRI-CUST-C3 — A match on a contact's email address shows the FULL value on the | E3: Failed — possible new problem | G3: Error: the note shows neither the whole value "zzautotest.nophone@staging.shopview.local" nor the text typed — it shows a different detail of the record altogether: ["Contact match: ZZAUTOTEST"] expect(received).toHaveLength(expected) Expected length: 0 Received length: 1 Received array: ["Contact match: ZZAUTOTEST"] 170 | expect(wrongValue, 171 | `the note shows neither the whole value "${term}" nor the text typed — it shows a ` + > 172 | `different detail of the record altogether: ${JSON.stringify(wrongValue)}`).toHaveLength(0); | ^ 173 | return; 174 | } 175 | at /tmp/claude-0/-home-user-Man | H3: Check it against the requirement as it reads today (not yet done), then decide whether to raise it. Nothing has been raised. | K3: C146202-C146282-sri-retest-full-value.spec.ts | L3: 83 | M3: 31.6
A4: C146233 | B4: Open case | C4: Run 415 | D4: C146233 — Parts: the whole part number is shown, with the typed part marked inside it | E4: Failed — possible new problem | G4: Error: row 1: the WHOLE value "ZZLONGROW Heavy Duty Air Brake" is highlighted rather than just the typed "ZZLONGROW" within it, so nothing marks which part actually matched expect(received).toBeGreaterThan(expected) Expected: > 0 Received: 0 260 | expect(unmarked.length, 261 | `row ${r.index}: the WHOLE value "${r.title.text}" is highlighted rather than just the ` + > 262 | `typed "${TERM}" within it, so nothing marks which part actually matched`).toBeGreaterThan(0); | ^ 263 | expect(r.title.clipped, 264 | `row ${r.index} is cut short — it paints ${r.title.clientW}px of ${r.title.scrollW}px an | H4: Check it against the requirement as it reads today (not yet done), then decide whether to raise it. Nothing has been raised. | K4: C146224-C146284-sri-entities.spec.ts | L4: 232 | M4: 9.8 | N4: Failed | O4: Error: row 1: the WHOLE value "ZZLONGROW Heavy Duty Air Brake" is highlighted rather than just the typed "ZZLONGROW" within it, so nothing marks which part actually matched expect(received).toBeGreaterThan(expected) Expected: > 0 Received: 0 282 | expect(unmarked.length, 283 | `row ${r.index}: the WHOLE value "${r.title.text}" is highlighted rather than just the ` + > 284 | `typed "${TERM}" within
A5: C146235 | B5: Open case | C5: Run 415 | D5: C146235 — Parts: the highlight marks the match inside the text, not instead of it | E5: Failed — possible new problem | G5: Error: row 1: every piece of "ZZLONGROW Heavy Duty Air Brake" is highlighted, so the mark covers the whole value instead of the typed "ZZLONGROW" inside it expect(received).toBe(expected) // Object.is equality Expected: true Received: false 315 | expect(r.title.segs.some((x) => !x.marked), 316 | `row ${r.index}: every piece of "${r.title.text}" is highlighted, so the mark covers the ` + > 317 | `whole value instead of the typed "${TERM}" inside it`).toBe(true); | ^ 318 | const rebuilt = r.title.segs.map((x) => x.text).join('').replace(/\s+/g, ' ').trim(); 319 | expect(rebuilt, `row ${r.index}: | H5: Check it against the requirement as it reads today (not yet done), then decide whether to raise it. Nothing has been raised. | K5: C146224-C146284-sri-entities.spec.ts | L5: 305 | M5: 9.8 | N5: Failed | O5: Error: row 1: every piece of "ZZLONGROW Heavy Duty Air Brake" is highlighted, so the mark covers the whole value instead of the typed "ZZLONGROW" inside it expect(received).toBe(expected) // Object.is equality Expected: true Received: false 336 | expect(r.title.segs.some((x) => !x.marked), 337 | `row ${r.index}: every piece of "${r.title.text}" is highlighted, so the mark covers the ` + > 338 | `w
A6: C146227 | B6: Open case | C6: Run 415 | D6: C146227 — Assets: two records sharing the typed text can be told apart | E6: Failed — possible new problem | G6: Error: these rows read identically to a person: ["ZZLONGROW-123786 · 2021 Rowcheck Trucks Longhauler | | ZZLONGROW Heavy Haulage And Trailer Repair Services Of Greater Fernvale 123786"] expect(received).toHaveLength(expected) Expected length: 0 Received length: 1 Received array: ["ZZLONGROW-123786 · 2021 Rowcheck Trucks Longhauler | | ZZLONGROW Heavy Haulage And Trailer Repair Services Of Greater Fernvale 123786"] 331 | const seen = rows.map(visibleRow); 332 | const dupes = seen.filter((v, i) => seen.indexOf(v) !== i); > 333 | expect(dupes, `these rows read identically to a person: ${JSON.stri | H6: Check it against the requirement as it reads today (not yet done), then decide whether to raise it. Nothing has been raised. | K6: C146224-C146284-sri-entities.spec.ts | L6: 324 | M6: 9.8 | N6: Failed | O6: Error: these rows read identically to a person: ["ZZLONGROW-123786 · 2021 Rowcheck Trucks Longhauler | | ZZLONGROW Heavy Haulage And Trailer Repair Services Of Greater Fernvale 123786"] expect(received).toHaveLength(expected) Expected length: 0 Received length: 1 Received array: ["ZZLONGROW-123786 · 2021 Rowcheck Trucks Longhauler | | ZZLONGROW Heavy Haulage And Trailer Repair Services Of Greater
A7: C146228 | B7: Open case | C7: Run 415 | D7: C146228 — Assets: records with the same bold line differ somewhere you can see | E7: Failed — possible new problem | G7: Error: rows 1,2 share the bold line "ZZLONGROW-123786 · 2021 Rowcheck Trucks Longhauler" and nothing visible separates them: [" | ZZLONGROW Heavy Haulage And Trailer Repair Services Of Greater Fernvale 123786"," | ZZLONGROW Heavy Haulage And Trailer Repair Services Of Greater Fernvale 123786"] expect(received).toBe(expected) // Object.is equality Expected: 2 Received: 1 348 | expect(new Set(rest).size, 349 | `rows ${group.map((r) => r.index).join(',')} share the bold line "${title}" and nothing visible ` + > 350 | `separates them: ${JSON.stringify(rest)}`).toBe(group.length); | ^ 351 | } 352 | | H7: Check it against the requirement as it reads today (not yet done), then decide whether to raise it. Nothing has been raised. | K7: C146224-C146284-sri-entities.spec.ts | L7: 336 | M7: 10 | N7: Failed | O7: Error: rows 1,2 share the bold line "ZZLONGROW-123786 · 2021 Rowcheck Trucks Longhauler" and nothing visible separates them: [" | ZZLONGROW Heavy Haulage And Trailer Repair Services Of Greater Fernvale 123786"," | ZZLONGROW Heavy Haulage And Trailer Repair Services Of Greater Fernvale 123786"] expect(received).toBe(expected) // Object.is equality Expected: 2 Received: 1 369 | expect(new Set(rest).
A8: C45137 | B8: Open case | C8: Run 415 | D8: C45137 — still-ordered purchase orders rank above received ones | E8: Failed — possible new problem | G8: Error: a received order is above a still-ordered one: ["Partial","Ordered","Ordered","Ordered","Ordered","Partial","Partial","Ordered","Partial","Partial","Partial","Received","Received","Received","Received","Ordered","Received","Received","Received"] expect(received).toBeLessThan(expected) Expected: < 11 Received: 15 70 | const firstReceived = seq.indexOf('Received'); 71 | if (lastOrdered >= 0 && firstReceived >= 0) { > 72 | expect(lastOrdered, `a received order is above a still-ordered one: ${JSON.stringify(seq)}`).toBeLessThan(firstReceived); | ^ 73 | } 74 | // NOT asserted: where "Partial | H8: Check it against the requirement as it reads today (not yet done), then decide whether to raise it. Nothing has been raised. | K8: counts-and-ranking.spec.ts | L8: 57 | M8: 19 | N8: Failed | O8: Error: a received order is above a still-ordered one: ["Partial","Ordered","Ordered","Ordered","Ordered","Partial","Partial","Ordered","Partial","Partial","Partial","Received","Received","Received","Received","Ordered","Received","Received","Received"] expect(received).toBeLessThan(expected) Expected: < 11 Received: 15 70 | const firstReceived = seq.indexOf('Received'); 71 | if (lastOrdered >= 0 &
A9: C44828 | B9: Open case | C9: Run 415 | D9: C44828 — the typed text is highlighted inside each matching row | E9: Failed — possible new problem | G9: Error: 65 of 65 rows carry no highlight at all expect(received).toBe(expected) // Object.is equality Expected: 0 Received: 65 264 | expect(r.length, `"${word}" finds nothing`).toBeGreaterThan(0); 265 | const unmarked = r.filter(x => x.marks.length === 0).length; > 266 | expect(unmarked, `${unmarked} of ${r.length} rows carry no highlight at all`).toBe(0); | ^ 267 | }); 268 | 269 | test('C44848 — a close match is drawn as a close match @C44848', async () => { at /tmp/claude-0/-home-user-Manual-test-Cases/126e0959-4bca-54ed-8b95-71a191ca38d1/scratchpad/clean3/repo/build/global-search/e2e/tests/f | H9: Check it against the requirement as it reads today (not yet done), then decide whether to raise it. Nothing has been raised. | K9: findability-matching.spec.ts | L9: 261 | M9: 8.1
A10: C146205 | B10: Open case | C10: Run 415 | D10: C146205 — SRI-WO-C4 — A match on line item descriptions (parts and labor on the WO) show | E10: Failed — already reported | G10: Error: these rows show only the characters typed instead of the whole value: ["Part number: \n786","Part number: \n786","Part description: \n786","Part description: \n786","Part description: \n786","Part description: \n786","Part description: \n786"] expect(received).toHaveLength(expected) Expected length: 0 Received length: 7 Received array: ["Part number:· 786", "Part number:· 786", "Part description:· 786", "Part description:· 786", "Part description:· 786", "Part description:· 786", "Part description:· 786"] 187 | expect(onlyTyped, 188 | `these rows show only the characters typed instead o | H10: Nothing new to raise: this is the behaviour SV-10634 describes (status Ready to Fix). It should pass once that fix reaches this build. | I10: SV-10634 | J10: Ready to Fix | K10: C146202-C146282-sri-retest-full-value.spec.ts | L10: 83 | M10: 17.7
A11: C146206 | B11: Open case | C11: Run 415 | D11: C146206 — SRI-WO-C5 — A match on part numbers on the work order's lines (`item_part_numb | E11: Failed — already reported | G11: Error: these rows show only the characters typed instead of the whole value: ["Part number: \n786","Part number: \n786","Part description: \n786","Part description: \n786","Part description: \n786","Part description: \n786","Part description: \n786"] expect(received).toHaveLength(expected) Expected length: 0 Received length: 7 Received array: ["Part number:· 786", "Part number:· 786", "Part description:· 786", "Part description:· 786", "Part description:· 786", "Part description:· 786", "Part description:· 786"] 187 | expect(onlyTyped, 188 | `these rows show only the characters typed instead o | H11: Nothing new to raise: this is the behaviour SV-10634 describes (status Ready to Fix). It should pass once that fix reaches this build. | I11: SV-10634 | J11: Ready to Fix | K11: C146202-C146282-sri-retest-full-value.spec.ts | L11: 83 | M11: 19.4
A12: C146238 | B12: Open case | C12: Run 415 | D12: C146238 — SRI-PART-C1 — A match on bin location shows the FULL value on the row | E12: Failed — already reported | G12: Error: these rows show only the characters typed instead of the whole value: ["Bin: \nH3B","Bin: \nH3B","Bin: \nH3B","Bin: \nH3B","Bin: \nH3B","Bin: \nH3B","Bin: \nH3B","Bin: \nH3B","Bin: \nH3B","Bin: \nH3B","Bin: \nH3B","Bin: \nH3B","Bin: \nH3B","Bin: \nH3B","Bin: \nH3B","Bin: \nH3B","Bin: \nH3B","Bin: \nH3B","Bin: \nH3B","Bin: \nH3B"] expect(received).toHaveLength(expected) Expected length: 0 Received length: 20 Received array: ["Bin:· H3B", "Bin:· H3B", "Bin:· H3B", "Bin:· H3B", "Bin:· H3B", "Bin:· H3B", "Bin:· H3B", "Bin:· H3B", "Bin:· H3B", "Bin:· H3B", …] 187 | expect(onlyTyped, 188 | `t | H12: Nothing new to raise: this is the behaviour SV-10634 describes (status Ready to Fix). It should pass once that fix reaches this build. | I12: SV-10634 | J12: Ready to Fix | K12: C146202-C146282-sri-retest-full-value.spec.ts | L12: 83 | M12: 17.6
A13: C146242 | B13: Open case | C13: Run 415 | D13: C146242 — SRI-PART-C5 — A match on tags shows the FULL value on the row | E13: Failed — already reported | G13: Error: these rows show only the characters typed instead of the whole value: ["Tag: \n496","Tag: \n496"] expect(received).toHaveLength(expected) Expected length: 0 Received length: 2 Received array: ["Tag:· 496", "Tag:· 496"] 187 | expect(onlyTyped, 188 | `these rows show only the characters typed instead of the whole value: ${JSON.stringify(onlyTyped)}`) > 189 | .toHaveLength(0); | ^ 190 | }); 191 | } 192 | at /tmp/claude-0/-home-user-Manual-test-Cases/126e0959-4bca-54ed-8b95-71a191ca38d1/scratchpad/clean3/repo/build/global-search/e2e/tests/C146202-C146282-sri-retest-full-value.spec.ts:189:8 | H13: Nothing new to raise: this is the behaviour SV-10634 describes (status Ready to Fix). It should pass once that fix reaches this build. | I13: SV-10634 | J13: Ready to Fix | K13: C146202-C146282-sri-retest-full-value.spec.ts | L13: 83 | M13: 18.4
A14: C146252 | B14: Open case | C14: Run 415 | D14: C146252 — SRI-VEND-C3 — A match on a contact's telephone shows the FULL value on the row | E14: Failed — already reported | G14: Error: these rows show only the characters typed instead of the whole value: ["Address: \n965","Contact match: \n965","Contact match: \n965","Contact match: \n965","Contact match: \n965","Contact match: \n965","Contact match: \n965"] expect(received).toHaveLength(expected) Expected length: 0 Received length: 7 Received array: ["Address:· 965", "Contact match:· 965", "Contact match:· 965", "Contact match:· 965", "Contact match:· 965", "Contact match:· 965", "Contact match:· 965"] 187 | expect(onlyTyped, 188 | `these rows show only the characters typed instead of the whole value: ${JSON.stringif | H14: Nothing new to raise: this is the behaviour SV-10634 describes (status Ready to Fix). It should pass once that fix reaches this build. | I14: SV-10634 | J14: Ready to Fix | K14: C146202-C146282-sri-retest-full-value.spec.ts | L14: 83 | M14: 17.6
A15: C146271 | B15: Open case | C15: Run 415 | D15: C146271 — SRI-PO-C1 — A match on part numbers on the PO shows the FULL value on the row | E15: Failed — already reported | G15: Error: these rows show only the characters typed instead of the whole value: ["Part number: \n0123"] expect(received).toHaveLength(expected) Expected length: 0 Received length: 1 Received array: ["Part number:· 0123"] 187 | expect(onlyTyped, 188 | `these rows show only the characters typed instead of the whole value: ${JSON.stringify(onlyTyped)}`) > 189 | .toHaveLength(0); | ^ 190 | }); 191 | } 192 | at /tmp/claude-0/-home-user-Manual-test-Cases/126e0959-4bca-54ed-8b95-71a191ca38d1/scratchpad/clean3/repo/build/global-search/e2e/tests/C146202-C146282-sri-retest-full-value.spec.ts:189:8 | H15: Nothing new to raise: this is the behaviour SV-10634 describes (status Ready to Fix). It should pass once that fix reaches this build. | I15: SV-10634 | J15: Ready to Fix | K15: C146202-C146282-sri-retest-full-value.spec.ts | L15: 83 | M15: 17.6
A16: C146272 | B16: Open case | C16: Run 415 | D16: C146272 — SRI-PO-C2 — A match on part descriptions on the PO shows the FULL value on the | E16: Failed — already reported | G16: Error: these rows show only the characters typed instead of the whole value: ["Part description: \n786","Part description: \n786","Part number: \n786","Part description: \n786"] expect(received).toHaveLength(expected) Expected length: 0 Received length: 4 Received array: ["Part description:· 786", "Part description:· 786", "Part number:· 786", "Part description:· 786"] 187 | expect(onlyTyped, 188 | `these rows show only the characters typed instead of the whole value: ${JSON.stringify(onlyTyped)}`) > 189 | .toHaveLength(0); | ^ 190 | }); 191 | } 192 | at /tmp/claude-0/-home-user-Manual-test-Ca | H16: Nothing new to raise: this is the behaviour SV-10634 describes (status Ready to Fix). It should pass once that fix reaches this build. | I16: SV-10634 | J16: Ready to Fix | K16: C146202-C146282-sri-retest-full-value.spec.ts | L16: 83 | M16: 19.2
A17: C146209 | B17: Open case | C17: Run 415 | D17: C146209 — each row shows the COMPLETE telephone, with the typed part inside it | E17: Failed — already reported | G17: Error: these rows show only the digits typed instead of the whole telephone: ["Contact match: \n0900","Contact match: \n0900","Contact match: \n0900","Contact match: \n0900","Contact match: \n0900","Contact match: \n0900","Contact match: \n0900","Contact match: \n0900","Contact match: \n0900","Contact match: \n0900","Contact match: \n0900","Contact match: \n0900","Contact match: \n0900","Contact match: \n0900","Contact match: \n0900"] expect(received).toHaveLength(expected) Expected length: 0 Received length: 15 Received array: ["Contact match:· 0900", "Contact match:· 0900", "Contact match:· | H17: Nothing new to raise: this is the behaviour SV-10634 describes (status Ready to Fix). It should pass once that fix reaches this build. | I17: SV-10634 | J17: Ready to Fix | K17: C146209-C146223-sri-customers.spec.ts | L17: 84 | M17: 9.7
A18: C146222 | B18: Open case | C18: Run 415 | D18: C146222 — the customer row shows every field the requirement names | E18: Failed — already reported | G18: Error: the customer row is missing ["telephone on hover"]. Row reads "7 Star Truck Repair 32 open 305 Harris Cape, Priscillabury, Nunavut". Hover added [] (pointer reached the row: true). expect(received).toHaveLength(expected) Expected length: 0 Received length: 1 Received array: ["telephone on hover"] 209 | expect(missing, `the customer row is missing ${JSON.stringify(missing)}. Row reads "${r.text}". ` + 210 | `Hover added ${JSON.stringify(hov.gained)} (pointer reached the row: ${hoverReached}).`) > 211 | .toHaveLength(0); | ^ 212 | }); 213 | 214 | test('C146223 — a soft match is drawn as a | H18: Nothing new to raise: this is the behaviour SV-10635 describes (status Ready to Fix). It should pass once that fix reaches this build. | I18: SV-10635 | J18: Ready to Fix | K18: C146209-C146223-sri-customers.spec.ts | L18: 162 | M18: 11.4
A19: C146245 | B19: Open case | C19: Run 415 | D19: C146245 — Vendors: the whole telephone is shown, with the typed part marked inside it | E19: Failed — our test's fault | G19: Error: CONTROL FAILED: no highlight found anywhere on row 8, so anything said below about an unhighlighted line is about this reader expect(received).toBeGreaterThan(expected) Expected: > 0 Received: 0 247 | expect(r.marks.length, 248 | `CONTROL FAILED: no highlight found anywhere on row ${r.index}, so anything said below about ` + > 249 | `an unhighlighted line is about this reader`).toBeGreaterThan(0); | ^ 250 | // …then the requirement itself: highlighted in the primary AND secondary text. 251 | expect(unmarkedLines(r, TERM), 252 | `row ${r.index}: the typed text is shown on these lines wit | H19: The test has been fixed. Re-run after the fix: Passed. | K19: C146224-C146284-sri-entities.spec.ts | L19: 232 | M19: 9.9 | N19: Passed
A20: C146266 | B20: Open case | C20: Run 415 | D20: C146266 — Purchase Orders: the whole PO number is shown, with the typed part marked inside it | E20: Failed — our test's fault | G20: Error: CONTROL FAILED: no highlight found anywhere on row 11, so anything said below about an unhighlighted line is about this reader expect(received).toBeGreaterThan(expected) Expected: > 0 Received: 0 247 | expect(r.marks.length, 248 | `CONTROL FAILED: no highlight found anywhere on row ${r.index}, so anything said below about ` + > 249 | `an unhighlighted line is about this reader`).toBeGreaterThan(0); | ^ 250 | // …then the requirement itself: highlighted in the primary AND secondary text. 251 | expect(unmarkedLines(r, TERM), 252 | `row ${r.index}: the typed text is shown on these lines wi | H20: The test has been fixed. Re-run after the fix: Passed. | K20: C146224-C146284-sri-entities.spec.ts | L20: 232 | M20: 9.8 | N20: Passed
A21: C146247 | B21: Open case | C21: Run 415 | D21: C146247 — Vendors: the highlight marks the match inside the text, not instead of it | E21: Failed — our test's fault | G21: Error: CONTROL FAILED: no highlight anywhere on row 8 expect(received).toBeGreaterThan(expected) Expected: > 0 Received: 0 310 | expect(rows.length).toBeGreaterThan(0); 311 | for (const r of rows) { > 312 | expect(r.marks.length, `CONTROL FAILED: no highlight anywhere on row ${r.index}`).toBeGreaterThan(0); | ^ 313 | expect(unmarkedLines(r, TERM), 314 | `row ${r.index}: the typed text appears on these lines unhighlighted`).toEqual([]); 315 | expect(r.title.segs.some((x) => !x.marked), at /tmp/claude-0/-home-user-Manual-test-Cases/126e0959-4bca-54ed-8b95-71a191ca38d1/scratchpad/clean3/repo/buil | H21: The test has been fixed. Re-run after the fix: Passed. | K21: C146224-C146284-sri-entities.spec.ts | L21: 305 | M21: 9.9 | N21: Passed
A22: C146268 | B22: Open case | C22: Run 415 | D22: C146268 — Purchase Orders: the highlight marks the match inside the text, not instead of it | E22: Failed — our test's fault | G22: Error: CONTROL FAILED: no highlight anywhere on row 11 expect(received).toBeGreaterThan(expected) Expected: > 0 Received: 0 310 | expect(rows.length).toBeGreaterThan(0); 311 | for (const r of rows) { > 312 | expect(r.marks.length, `CONTROL FAILED: no highlight anywhere on row ${r.index}`).toBeGreaterThan(0); | ^ 313 | expect(unmarkedLines(r, TERM), 314 | `row ${r.index}: the typed text appears on these lines unhighlighted`).toEqual([]); 315 | expect(r.title.segs.some((x) => !x.marked), at /tmp/claude-0/-home-user-Manual-test-Cases/126e0959-4bca-54ed-8b95-71a191ca38d1/scratchpad/clean3/repo/bui | H22: The test has been fixed. Re-run after the fix: Passed. | K22: C146224-C146284-sri-entities.spec.ts | L22: 305 | M22: 9.9 | N22: Passed
A23: C146306 | B23: Open case | C23: Run 415 | D23: C146306 — someone without access sees no rows AND no count | E23: Failed — our test's fault | G23: Error: Staging needs a live session cookie. Sign in to app.staging.shopview.com in a browser, then set GS_SSO and GS_PHPSESSID (and GS_CF if Cloudflare is in front) — or point GS_STAGING_ENVF at a file holding SV_SSO_SESSION=, PHPSESSID= and CF_CLEARANCE=. Staging uses Google sign-in, so there is no username and password to script. See e2e/.env.example. at ../fixtures/boot.ts:421 419 | const valueOf = (name: string) => SOURCES.find(([n]) => n === name)?.[1] ?? ''; 420 | if (!valueOf('sv_sso_session') || !valueOf('PHPSESSID')) { > 421 | throw new Error( | ^ 422 | 'Staging needs a live session c | H23: The test has been fixed. Re-run after the fix: Passed. | K23: C146285-C146306-sri-all-tab.spec.ts | L23: 368 | M23: 6.9 | N23: Passed
A24: C44809 | B24: Open case | C24: Run 415 | D24: C44809 — Down and Up move the highlight across result rows only | E24: Failed — our test's fault | G24: TimeoutError: locator.click: Timeout 60000ms exceeded. Call log: - waiting for locator('.search-modal input') - locator resolved to <input value="" type="text" tabindex="0" role="combobox" autocorrect="off" autocomplete="off" spellcheck="false" aria-label="Search" aria-expanded="true" autocapitalize="off" data-autofocus="true" enterkeyhint="search" aria-autocomplete="list" data-test-id="search_modal_input" aria-controls="search_modal_listbox" class="q-field__native q-placeholder" id="f_1fbe4b4b-e83a-485d-80e8-c9e8618fdbe0" placeholder="Search work orders, customers, parts and more" aria-active | H24: The test has been fixed. Re-run after the fix: Passed. | K24: C44804-C55683-panel-keyboard.spec.ts | L24: 76 | M24: 63.5 | N24: Passed
A25: C45144 | B25: Open case | C25: Run 415 | D25: C45144 — parts appear only with Catalog & Inventory access | E25: Failed — our test's fault | G25: Error: parts hidden with access granted expect(received).toBeGreaterThan(expected) Expected: > 0 Received: 0 110 | expect((await search(s.page, FIXTURE)).counts['Parts'] ?? 0, 'parts shown without access').toBeFalsy(); 111 | await asTechnicianWith([...new Set([...all, parts])]); > 112 | expect((await search(s.page, FIXTURE)).counts['Parts'] ?? 0, 'parts hidden with access granted').toBeGreaterThan(0); | ^ 113 | }); 114 | 115 | test('C45146 — removing customer access removes customers AND vehicles @C45146', async () => { at /tmp/claude-0/-home-user-Manual-test-Cases/126e0959-4bca-54ed-8b95-71a1 | H25: The test has been fixed. Re-run after the fix: Passed. | K25: access-and-location.spec.ts | L25: 103 | M25: 27.8 | N25: Passed
A26: C45146 | B26: Open case | C26: Run 415 | D26: C45146 — removing customer access removes customers AND vehicles | E26: Failed — our test's fault | G26: Error: customers still shown expect(received).toBeFalsy() Received: 20 121 | await asTechnicianWith(all.filter((id: string) => id !== cust)); 122 | const p = await search(s.page, FIXTURE); > 123 | expect(p.counts['Customers'] ?? 0, 'customers still shown').toBeFalsy(); | ^ 124 | expect(p.counts['Assets'] ?? 0, 'vehicles still shown — they depend on customer access too').toBeFalsy(); 125 | }); 126 | at /tmp/claude-0/-home-user-Manual-test-Cases/126e0959-4bca-54ed-8b95-71a191ca38d1/scratchpad/clean3/repo/build/global-search/e2e/tests/access-and-location.spec.ts:123:63 | H26: The test has been fixed. Re-run after the fix: Passed. | K26: access-and-location.spec.ts | L26: 115 | M26: 12.6 | N26: Passed
A27: C45147 | B27: Open case | C27: Run 415 | D27: C45147 — a time-clock-only person gets nothing at all | E27: Failed — our test's fault | G27: Error: All returned results expect(received).toBeFalsy() Received: 124 131 | await asTechnicianWith(idsOf(['timesheetsView'])); 132 | const p = await search(s.page, FIXTURE); > 133 | for (const [tab, v] of Object.entries(p.counts)) expect(v ?? 0, `${tab} returned results`).toBeFalsy(); | ^ 134 | }); 135 | 136 | /** at /tmp/claude-0/-home-user-Manual-test-Cases/126e0959-4bca-54ed-8b95-71a191ca38d1/scratchpad/clean3/repo/build/global-search/e2e/tests/access-and-location.spec.ts:133:94 | H27: The test has been fixed. Re-run after the fix: Passed. | K27: access-and-location.spec.ts | L27: 127 | M27: 12.9 | N27: Passed
A28: C45143 | B28: Open case | C28: Run 415 | D28: C45143 — a part-sales role sees part sales but not parts or suppliers | E28: Failed — our test's fault | G28: Error: parts shown to a part-sales-only role expect(received).toBeFalsy() Received: 15 158 | const p = await search(s.page, FIXTURE); 159 | expect(p.counts['Part sales'] ?? 0, 'part sales hidden from a part-sales role').toBeGreaterThan(0); > 160 | expect(p.counts['Parts'] ?? 0, 'parts shown to a part-sales-only role').toBeFalsy(); | ^ 161 | expect(p.counts['Vendors'] ?? 0, 'suppliers shown to a part-sales-only role').toBeFalsy(); 162 | }); 163 | at /tmp/claude-0/-home-user-Manual-test-Cases/126e0959-4bca-54ed-8b95-71a191ca38d1/scratchpad/clean3/repo/build/global-search/e2e/tests/access-and-loc | H28: The test has been fixed. Re-run after the fix: Passed. | K28: access-and-location.spec.ts | L28: 143 | M28: 12.5 | N28: Passed
A29: C45151 | B29: Open case | C29: Run 415 | D29: C45151 · C45152 · C55684 — search is limited to the shop you are in, and follows you | E29: Failed — our test's fault | G29: Error: a job could not be created at each shop expect(received).toBeTruthy() Received: undefined 190 | if (label === 'heavy') heavyJob = num; else lethJob = num; 191 | } > 192 | expect(heavyJob && lethJob, 'a job could not be created at each shop').toBeTruthy(); | ^ 193 | await s.page.waitForTimeout(30_000); 194 | 195 | const readAt = async (wp: string) => { at /tmp/claude-0/-home-user-Manual-test-Cases/126e0959-4bca-54ed-8b95-71a191ca38d1/scratchpad/clean3/repo/build/global-search/e2e/tests/access-and-location.spec.ts:192:76 | H29: The test has been fixed. Re-run after the fix: Passed. | K29: access-and-location.spec.ts | L29: 173 | M29: 4.8 | N29: Passed
A30: C55716 | B30: Open case | C30: Run 415 | D30: C55716 — the record changed most recently is listed first [expected to fail: SV-10340] | E30: Failed — our test's fault | G30: TypeError: Cannot read properties of undefined (reading 'id') 144 | const mine = ((list.body as any)?.data?.collection ?? []).filter((v: any) => String(v.name).includes(tag)); 145 | const target = mine[1] ?? mine[0]; > 146 | const w = await api(s.page, 'POST', '/api/parts-catalogue/change-vendor', { ...target, vendor_id: target.id, id: target.id, name: lowered }); | ^ 147 | expect(w.status, `the rename was refused: ${w.text}`).toBeLessThan(400); 148 | 149 | // The edit appearing in the results IS the proof the entry rebuilt. Without it, a stale order at /tmp/claude-0/-home-user-Manual-test-Cas | H30: The test has been fixed. Re-run after the fix: Passed. | I30: SV-10340 | J30: OBSOLETE | K30: counts-and-ranking.spec.ts | L30: 105 | M30: 19.8 | N30: Passed
A31: C55724 | B31: Open case | C31: Run 415 | D31: C55724b — a name starting with the query ranks above one that only contains it (seeded) | E31: Failed — our test's fault | G31: Error: page.evaluate: TypeError: Failed to fetch (api.shopview.com) at https://app.staging.shopview.com/js/sentry.B6EvyTlO.js:17:8323 at eval (eval at evaluate (:290:30), <anonymous>:2:21) at UtilityScript.evaluate (<anonymous>:292:16) at UtilityScript.<anonymous> (<anonymous>:1:44) at https://app.staging.shopview.com/js/sentry.B6EvyTlO.js:17:8323 at eval (eval at evaluate (:290:30), <anonymous>:2:21) at UtilityScript.evaluate (<anonymous>:292:16) at UtilityScript.<anonymous> (<anonymous>:1:44) at createCustomer (/tmp/claude-0/-home-user-Manual-test-Cases/126e0959-4bca-54ed-8b95-71a191ca38d1/s | H31: The test has been fixed. Re-run after the fix: Passed. | K31: ranking-seeded.spec.ts | L31: 85 | M31: 0.8 | N31: Passed
A32: C55723 | B32: Open case | C32: Run 415 | D32: C55723 — a record matched on its name ranks above one matched on a lesser field | E32: Failed — our test's fault | G32: Error: page.evaluate: TypeError: Failed to fetch (api.shopview.com) at https://app.staging.shopview.com/js/sentry.B6EvyTlO.js:17:8323 at eval (eval at evaluate (:290:30), <anonymous>:2:21) at UtilityScript.evaluate (<anonymous>:292:16) at UtilityScript.<anonymous> (<anonymous>:1:44) at https://app.staging.shopview.com/js/sentry.B6EvyTlO.js:17:8323 at eval (eval at evaluate (:290:30), <anonymous>:2:21) at UtilityScript.evaluate (<anonymous>:292:16) at UtilityScript.<anonymous> (<anonymous>:1:44) at createCustomer (/tmp/claude-0/-home-user-Manual-test-Cases/126e0959-4bca-54ed-8b95-71a191ca38d1/s | H32: The test has been fixed. Re-run after the fix: Passed. | K32: ranking-seeded.spec.ts | L32: 98 | M32: 0.6 | N32: Passed
A33: C45139 | B33: Open case | C33: Run 415 | D33: C45139 — a match in a lesser field still finds the company | E33: Failed — our test's fault | G33: Error: page.evaluate: TypeError: Failed to fetch (api.shopview.com) at https://app.staging.shopview.com/js/sentry.B6EvyTlO.js:17:8323 at eval (eval at evaluate (:290:30), <anonymous>:2:21) at UtilityScript.evaluate (<anonymous>:292:16) at UtilityScript.<anonymous> (<anonymous>:1:44) at https://app.staging.shopview.com/js/sentry.B6EvyTlO.js:17:8323 at eval (eval at evaluate (:290:30), <anonymous>:2:21) at UtilityScript.evaluate (<anonymous>:292:16) at UtilityScript.<anonymous> (<anonymous>:1:44) at createCustomer (/tmp/claude-0/-home-user-Manual-test-Cases/126e0959-4bca-54ed-8b95-71a191ca38d1/s | H33: The test has been fixed. Re-run after the fix: Passed. | K33: ranking-seeded.spec.ts | L33: 115 | M33: 0.6 | N33: Passed
A34: C53586 | B34: Open case | C34: Run 415 | D34: C53586 — a newly created customer is findable within 30 seconds | E34: Failed — our test's fault | G34: Error: page.evaluate: TypeError: Failed to fetch (api.shopview.com) at https://app.staging.shopview.com/js/sentry.B6EvyTlO.js:17:8323 at eval (eval at evaluate (:290:30), <anonymous>:2:21) at UtilityScript.evaluate (<anonymous>:292:16) at UtilityScript.<anonymous> (<anonymous>:1:44) at https://app.staging.shopview.com/js/sentry.B6EvyTlO.js:17:8323 at eval (eval at evaluate (:290:30), <anonymous>:2:21) at UtilityScript.evaluate (<anonymous>:292:16) at UtilityScript.<anonymous> (<anonymous>:1:44) at createCustomer (/tmp/claude-0/-home-user-Manual-test-Cases/126e0959-4bca-54ed-8b95-71a191ca38d1/s | H34: The test has been fixed. Re-run after the fix: Passed. | K34: ranking-seeded.spec.ts | L34: 126 | M34: 0.6 | N34: Passed
A35: C53587 | B35: Open case | C35: Run 415 | D35: C53587 — a newly created record of another kind is findable within 30 seconds | E35: Failed — our test's fault | G35: Error: page.evaluate: TypeError: Failed to fetch (api.shopview.com) at https://app.staging.shopview.com/js/sentry.B6EvyTlO.js:17:8323 at eval (eval at evaluate (:290:30), <anonymous>:2:21) at UtilityScript.evaluate (<anonymous>:292:16) at UtilityScript.<anonymous> (<anonymous>:1:44) at https://app.staging.shopview.com/js/sentry.B6EvyTlO.js:17:8323 at eval (eval at evaluate (:290:30), <anonymous>:2:21) at UtilityScript.evaluate (<anonymous>:292:16) at UtilityScript.<anonymous> (<anonymous>:1:44) at createCustomer (/tmp/claude-0/-home-user-Manual-test-Cases/126e0959-4bca-54ed-8b95-71a191ca38d1/s | H35: The test has been fixed. Re-run after the fix: Passed. | K35: ranking-seeded.spec.ts | L35: 137 | M35: 0.7 | N35: Passed
A36: C55712 | B36: Open case | C36: Run 415 | D36: C55712 — Parts: what is relevant to where you are is still found from there | E36: Failed — our test's fault | G36: Error: expect(locator).toBeVisible() failed Locator: locator('.search-modal') Expected: visible Timeout: 20000ms Error: element(s) not found Call log: - Expect "toBeVisible" with timeout 20000ms - waiting for locator('.search-modal') at ../fixtures/search.ts:28 26 | const already = await page.locator(SEL.modal).count(); 27 | if (!already) { await page.keyboard.press('Control+k'); await page.waitForTimeout(1_400); } > 28 | await expect(page.locator(SEL.modal)).toBeVisible(); | ^ 29 | } 30 | 31 | export async function closePanel(page: Page) { at openPanel (/tmp/claude-0/-home-user-Manual-test-Ca | H36: The test has been fixed. Re-run after the fix: Passed. | K36: ranking-seeded.spec.ts | L36: 184 | M36: 21.9 | N36: Passed
A37: C146202 | B37: Open case | C37: Run 415 | D37: C146202 — SRI-WO-C1 — A match on VIN / serial number shows the FULL value on the row | E37: Known fault — still there | G37: Failed in the known way. The fault recorded under None is still there. | H37: Nothing new. Already known; waiting on the fix. | K37: C146202-C146282-sri-retest-full-value.spec.ts | L37: 83 | M37: 30.4
A38: C146214 | B38: Open case | C38: Run 415 | D38: C146214 — SRI-CUST-C1 — A match on the customer's own telephone shows the FULL value on | E38: Known fault — still there | G38: Failed in the known way. The fault recorded under None is still there. | H38: Nothing new. Already known; waiting on the fix. | K38: C146202-C146282-sri-retest-full-value.spec.ts | L38: 83 | M38: 29.5
A39: C146215 | B39: Open case | C39: Run 415 | D39: C146215 — SRI-CUST-C2 — A match on a contact's telephone shows the FULL value on the row | E39: Known fault — still there | G39: Failed in the known way. The fault recorded under None is still there. | H39: Nothing new. Already known; waiting on the fix. | K39: C146202-C146282-sri-retest-full-value.spec.ts | L39: 83 | M39: 28.3
A40: C146217 | B40: Open case | C40: Run 415 | D40: C146217 — SRI-CUST-C4 — A match on a contact's name shows the FULL value on the row | E40: Known fault — still there | G40: Failed in the known way. The fault recorded under None is still there. | H40: Nothing new. Already known; waiting on the fix. | K40: C146202-C146282-sri-retest-full-value.spec.ts | L40: 83 | M40: 29.1
...

Sheet Possible new problems
A1: Failures not described by any ticket. NOT yet checked against the requirement as it reads today, and nothing has been raised.
A2: Case | B2: Case in TestRail | C2: Test run | D2: What the test checks | E2: Result | F2: Likely cause | G2: What happened | H2: What needs to be done | I2: Ticket | J2: Ticket status (read live) | K2: Spec file | L2: Line | M2: Seconds | N2: Re-run after fixing the test | O2: Re-run detail
A3: C146216 | B3: Open case | C3: Run 415 | D3: C146216 — SRI-CUST-C3 — A match on a contact's email address shows the FULL value on the | E3: Failed — possible new problem | G3: Error: the note shows neither the whole value "zzautotest.nophone@staging.shopview.local" nor the text typed — it shows a different detail of the record altogether: ["Contact match: ZZAUTOTEST"] expect(received).toHaveLength(expected) Expected length: 0 Received length: 1 Received array: ["Contact match: ZZAUTOTEST"] 170 | expect(wrongValue, 171 | `the note shows neither the whole value "${term}" nor the text typed — it shows a ` + > 172 | `different detail of the record altogether: ${JSON.stringify(wrongValue)}`).toHaveLength(0); | ^ 173 | return; 174 | } 175 | at /tmp/claude-0/-home-user-Man | H3: Check it against the requirement as it reads today (not yet done), then decide whether to raise it. Nothing has been raised. | K3: C146202-C146282-sri-retest-full-value.spec.ts | L3: 83 | M3: 31.6
A4: C146233 | B4: Open case | C4: Run 415 | D4: C146233 — Parts: the whole part number is shown, with the typed part marked inside it | E4: Failed — possible new problem | G4: Error: row 1: the WHOLE value "ZZLONGROW Heavy Duty Air Brake" is highlighted rather than just the typed "ZZLONGROW" within it, so nothing marks which part actually matched expect(received).toBeGreaterThan(expected) Expected: > 0 Received: 0 260 | expect(unmarked.length, 261 | `row ${r.index}: the WHOLE value "${r.title.text}" is highlighted rather than just the ` + > 262 | `typed "${TERM}" within it, so nothing marks which part actually matched`).toBeGreaterThan(0); | ^ 263 | expect(r.title.clipped, 264 | `row ${r.index} is cut short — it paints ${r.title.clientW}px of ${r.title.scrollW}px an | H4: Check it against the requirement as it reads today (not yet done), then decide whether to raise it. Nothing has been raised. | K4: C146224-C146284-sri-entities.spec.ts | L4: 232 | M4: 9.8 | N4: Failed | O4: Error: row 1: the WHOLE value "ZZLONGROW Heavy Duty Air Brake" is highlighted rather than just the typed "ZZLONGROW" within it, so nothing marks which part actually matched expect(received).toBeGreaterThan(expected) Expected: > 0 Received: 0 282 | expect(unmarked.length, 283 | `row ${r.index}: the WHOLE value "${r.title.text}" is highlighted rather than just the ` + > 284 | `typed "${TERM}" within
A5: C146235 | B5: Open case | C5: Run 415 | D5: C146235 — Parts: the highlight marks the match inside the text, not instead of it | E5: Failed — possible new problem | G5: Error: row 1: every piece of "ZZLONGROW Heavy Duty Air Brake" is highlighted, so the mark covers the whole value instead of the typed "ZZLONGROW" inside it expect(received).toBe(expected) // Object.is equality Expected: true Received: false 315 | expect(r.title.segs.some((x) => !x.marked), 316 | `row ${r.index}: every piece of "${r.title.text}" is highlighted, so the mark covers the ` + > 317 | `whole value instead of the typed "${TERM}" inside it`).toBe(true); | ^ 318 | const rebuilt = r.title.segs.map((x) => x.text).join('').replace(/\s+/g, ' ').trim(); 319 | expect(rebuilt, `row ${r.index}: | H5: Check it against the requirement as it reads today (not yet done), then decide whether to raise it. Nothing has been raised. | K5: C146224-C146284-sri-entities.spec.ts | L5: 305 | M5: 9.8 | N5: Failed | O5: Error: row 1: every piece of "ZZLONGROW Heavy Duty Air Brake" is highlighted, so the mark covers the whole value instead of the typed "ZZLONGROW" inside it expect(received).toBe(expected) // Object.is equality Expected: true Received: false 336 | expect(r.title.segs.some((x) => !x.marked), 337 | `row ${r.index}: every piece of "${r.title.text}" is highlighted, so the mark covers the ` + > 338 | `w
A6: C146227 | B6: Open case | C6: Run 415 | D6: C146227 — Assets: two records sharing the typed text can be told apart | E6: Failed — possible new problem | G6: Error: these rows read identically to a person: ["ZZLONGROW-123786 · 2021 Rowcheck Trucks Longhauler | | ZZLONGROW Heavy Haulage And Trailer Repair Services Of Greater Fernvale 123786"] expect(received).toHaveLength(expected) Expected length: 0 Received length: 1 Received array: ["ZZLONGROW-123786 · 2021 Rowcheck Trucks Longhauler | | ZZLONGROW Heavy Haulage And Trailer Repair Services Of Greater Fernvale 123786"] 331 | const seen = rows.map(visibleRow); 332 | const dupes = seen.filter((v, i) => seen.indexOf(v) !== i); > 333 | expect(dupes, `these rows read identically to a person: ${JSON.stri | H6: Check it against the requirement as it reads today (not yet done), then decide whether to raise it. Nothing has been raised. | K6: C146224-C146284-sri-entities.spec.ts | L6: 324 | M6: 9.8 | N6: Failed | O6: Error: these rows read identically to a person: ["ZZLONGROW-123786 · 2021 Rowcheck Trucks Longhauler | | ZZLONGROW Heavy Haulage And Trailer Repair Services Of Greater Fernvale 123786"] expect(received).toHaveLength(expected) Expected length: 0 Received length: 1 Received array: ["ZZLONGROW-123786 · 2021 Rowcheck Trucks Longhauler | | ZZLONGROW Heavy Haulage And Trailer Repair Services Of Greater
A7: C146228 | B7: Open case | C7: Run 415 | D7: C146228 — Assets: records with the same bold line differ somewhere you can see | E7: Failed — possible new problem | G7: Error: rows 1,2 share the bold line "ZZLONGROW-123786 · 2021 Rowcheck Trucks Longhauler" and nothing visible separates them: [" | ZZLONGROW Heavy Haulage And Trailer Repair Services Of Greater Fernvale 123786"," | ZZLONGROW Heavy Haulage And Trailer Repair Services Of Greater Fernvale 123786"] expect(received).toBe(expected) // Object.is equality Expected: 2 Received: 1 348 | expect(new Set(rest).size, 349 | `rows ${group.map((r) => r.index).join(',')} share the bold line "${title}" and nothing visible ` + > 350 | `separates them: ${JSON.stringify(rest)}`).toBe(group.length); | ^ 351 | } 352 | | H7: Check it against the requirement as it reads today (not yet done), then decide whether to raise it. Nothing has been raised. | K7: C146224-C146284-sri-entities.spec.ts | L7: 336 | M7: 10 | N7: Failed | O7: Error: rows 1,2 share the bold line "ZZLONGROW-123786 · 2021 Rowcheck Trucks Longhauler" and nothing visible separates them: [" | ZZLONGROW Heavy Haulage And Trailer Repair Services Of Greater Fernvale 123786"," | ZZLONGROW Heavy Haulage And Trailer Repair Services Of Greater Fernvale 123786"] expect(received).toBe(expected) // Object.is equality Expected: 2 Received: 1 369 | expect(new Set(rest).
A8: C45137 | B8: Open case | C8: Run 415 | D8: C45137 — still-ordered purchase orders rank above received ones | E8: Failed — possible new problem | G8: Error: a received order is above a still-ordered one: ["Partial","Ordered","Ordered","Ordered","Ordered","Partial","Partial","Ordered","Partial","Partial","Partial","Received","Received","Received","Received","Ordered","Received","Received","Received"] expect(received).toBeLessThan(expected) Expected: < 11 Received: 15 70 | const firstReceived = seq.indexOf('Received'); 71 | if (lastOrdered >= 0 && firstReceived >= 0) { > 72 | expect(lastOrdered, `a received order is above a still-ordered one: ${JSON.stringify(seq)}`).toBeLessThan(firstReceived); | ^ 73 | } 74 | // NOT asserted: where "Partial | H8: Check it against the requirement as it reads today (not yet done), then decide whether to raise it. Nothing has been raised. | K8: counts-and-ranking.spec.ts | L8: 57 | M8: 19 | N8: Failed | O8: Error: a received order is above a still-ordered one: ["Partial","Ordered","Ordered","Ordered","Ordered","Partial","Partial","Ordered","Partial","Partial","Partial","Received","Received","Received","Received","Ordered","Received","Received","Received"] expect(received).toBeLessThan(expected) Expected: < 11 Received: 15 70 | const firstReceived = seq.indexOf('Received'); 71 | if (lastOrdered >= 0 &
A9: C44828 | B9: Open case | C9: Run 415 | D9: C44828 — the typed text is highlighted inside each matching row | E9: Failed — possible new problem | G9: Error: 65 of 65 rows carry no highlight at all expect(received).toBe(expected) // Object.is equality Expected: 0 Received: 65 264 | expect(r.length, `"${word}" finds nothing`).toBeGreaterThan(0); 265 | const unmarked = r.filter(x => x.marks.length === 0).length; > 266 | expect(unmarked, `${unmarked} of ${r.length} rows carry no highlight at all`).toBe(0); | ^ 267 | }); 268 | 269 | test('C44848 — a close match is drawn as a close match @C44848', async () => { at /tmp/claude-0/-home-user-Manual-test-Cases/126e0959-4bca-54ed-8b95-71a191ca38d1/scratchpad/clean3/repo/build/global-search/e2e/tests/f | H9: Check it against the requirement as it reads today (not yet done), then decide whether to raise it. Nothing has been raised. | K9: findability-matching.spec.ts | L9: 261 | M9: 8.1

Sheet Already reported
A1: Failures showing a behaviour a filed ticket already describes. The ticket and its live status are on each row. Nothing new to raise.
A2: Case | B2: Case in TestRail | C2: Test run | D2: What the test checks | E2: Result | F2: Likely cause | G2: What happened | H2: What needs to be done | I2: Ticket | J2: Ticket status (read live) | K2: Spec file | L2: Line | M2: Seconds | N2: Re-run after fixing the test | O2: Re-run detail
A3: C146205 | B3: Open case | C3: Run 415 | D3: C146205 — SRI-WO-C4 — A match on line item descriptions (parts and labor on the WO) show | E3: Failed — already reported | G3: Error: these rows show only the characters typed instead of the whole value: ["Part number: \n786","Part number: \n786","Part description: \n786","Part description: \n786","Part description: \n786","Part description: \n786","Part description: \n786"] expect(received).toHaveLength(expected) Expected length: 0 Received length: 7 Received array: ["Part number:· 786", "Part number:· 786", "Part description:· 786", "Part description:· 786", "Part description:· 786", "Part description:· 786", "Part description:· 786"] 187 | expect(onlyTyped, 188 | `these rows show only the characters typed instead o | H3: Nothing new to raise: this is the behaviour SV-10634 describes (status Ready to Fix). It should pass once that fix reaches this build. | I3: SV-10634 | J3: Ready to Fix | K3: C146202-C146282-sri-retest-full-value.spec.ts | L3: 83 | M3: 17.7
A4: C146206 | B4: Open case | C4: Run 415 | D4: C146206 — SRI-WO-C5 — A match on part numbers on the work order's lines (`item_part_numb | E4: Failed — already reported | G4: Error: these rows show only the characters typed instead of the whole value: ["Part number: \n786","Part number: \n786","Part description: \n786","Part description: \n786","Part description: \n786","Part description: \n786","Part description: \n786"] expect(received).toHaveLength(expected) Expected length: 0 Received length: 7 Received array: ["Part number:· 786", "Part number:· 786", "Part description:· 786", "Part description:· 786", "Part description:· 786", "Part description:· 786", "Part description:· 786"] 187 | expect(onlyTyped, 188 | `these rows show only the characters typed instead o | H4: Nothing new to raise: this is the behaviour SV-10634 describes (status Ready to Fix). It should pass once that fix reaches this build. | I4: SV-10634 | J4: Ready to Fix | K4: C146202-C146282-sri-retest-full-value.spec.ts | L4: 83 | M4: 19.4
A5: C146238 | B5: Open case | C5: Run 415 | D5: C146238 — SRI-PART-C1 — A match on bin location shows the FULL value on the row | E5: Failed — already reported | G5: Error: these rows show only the characters typed instead of the whole value: ["Bin: \nH3B","Bin: \nH3B","Bin: \nH3B","Bin: \nH3B","Bin: \nH3B","Bin: \nH3B","Bin: \nH3B","Bin: \nH3B","Bin: \nH3B","Bin: \nH3B","Bin: \nH3B","Bin: \nH3B","Bin: \nH3B","Bin: \nH3B","Bin: \nH3B","Bin: \nH3B","Bin: \nH3B","Bin: \nH3B","Bin: \nH3B","Bin: \nH3B"] expect(received).toHaveLength(expected) Expected length: 0 Received length: 20 Received array: ["Bin:· H3B", "Bin:· H3B", "Bin:· H3B", "Bin:· H3B", "Bin:· H3B", "Bin:· H3B", "Bin:· H3B", "Bin:· H3B", "Bin:· H3B", "Bin:· H3B", …] 187 | expect(onlyTyped, 188 | `t | H5: Nothing new to raise: this is the behaviour SV-10634 describes (status Ready to Fix). It should pass once that fix reaches this build. | I5: SV-10634 | J5: Ready to Fix | K5: C146202-C146282-sri-retest-full-value.spec.ts | L5: 83 | M5: 17.6
A6: C146242 | B6: Open case | C6: Run 415 | D6: C146242 — SRI-PART-C5 — A match on tags shows the FULL value on the row | E6: Failed — already reported | G6: Error: these rows show only the characters typed instead of the whole value: ["Tag: \n496","Tag: \n496"] expect(received).toHaveLength(expected) Expected length: 0 Received length: 2 Received array: ["Tag:· 496", "Tag:· 496"] 187 | expect(onlyTyped, 188 | `these rows show only the characters typed instead of the whole value: ${JSON.stringify(onlyTyped)}`) > 189 | .toHaveLength(0); | ^ 190 | }); 191 | } 192 | at /tmp/claude-0/-home-user-Manual-test-Cases/126e0959-4bca-54ed-8b95-71a191ca38d1/scratchpad/clean3/repo/build/global-search/e2e/tests/C146202-C146282-sri-retest-full-value.spec.ts:189:8 | H6: Nothing new to raise: this is the behaviour SV-10634 describes (status Ready to Fix). It should pass once that fix reaches this build. | I6: SV-10634 | J6: Ready to Fix | K6: C146202-C146282-sri-retest-full-value.spec.ts | L6: 83 | M6: 18.4
