Workbook

Sheet How to run this
A1: Search Results Integrity — manual test pack
A3: Where to run it: https://app.staging.shopview.com · workplace: Staging Heavy Duty - 9919
A4: Sign in with any account that can see all of: Work Orders, Customers, Assets, Parts, Vendors, Part Sales, Purchase Orders and Vendor Invoices.
A5: Open search with the magnifying glass in the header, or press Ctrl+K (Cmd+K on a Mac).
A7: What this pack is for
A8: These tests do NOT check whether search finds the right record. They check whether the row you are looking at TELLS YOU WHAT YOU NEED TO KNOW — so you can pick the right record without opening it, and tell two similar records apart.
A9: It came out of SV-10619 and SV-10551. Both are the same problem: you type 123786 and a row shows you only 786 — which is also what a row for 185786 would show.
A11: Where these live in TestRail
A12: All 110 cases are in TestRail under Global Search > Global Search - Enhancement (Aug 2026) > Search Results Integrity — result row display (SV-10619 / SV-10551), in nine folders, one per tab.
A13: They are all in test run 415, "Global Search V2 — Full Suite": https://shopview.testrail.io/index.php?/runs/view/415
A14: The TestRail column in each sheet links straight to that case. Record your result in TestRail; this sheet is for working through them.
A16: How to read a row
... A28: Write exactly what you typed and exactly what the row showed, and take a screenshot of the whole row. "It was wrong" cannot be fixed by a developer; "I typed 965 and the row showed 9..." can.

Sheet Summary
A1: Search Results Integrity — progress
A3: Environment: https://app.staging.shopview.com · workplace: Staging Heavy Duty - 9919
A5: Tab | B5: Tests | C5: Pass | D5: Fail | E5: Blocked | F5: Not run | G5: Held | H5: Recorded
A6: Work Orders | B6: 12 | C6: =COUNTIF('Work Orders'!$K$2:$K$13,"Pass") | D6: =COUNTIF('Work Orders'!$K$2:$K$13,"Fail") | E6: =COUNTIF('Work Orders'!$K$2:$K$13,"Blocked") | F6: =COUNTIF('Work Orders'!$K$2:$K$13,"Not run") | G6: =COUNTIF('Work Orders'!$K$2:$K$13,"HELD - do not run") | H6: =SUM(C6:G6)
A7: Customers | B7: 16 | C7: =COUNTIF('Customers'!$K$2:$K$17,"Pass") | D7: =COUNTIF('Customers'!$K$2:$K$17,"Fail") | E7: =COUNTIF('Customers'!$K$2:$K$17,"Blocked") | F7: =COUNTIF('Customers'!$K$2:$K$17,"Not run") | G7: =COUNTIF('Customers'!$K$2:$K$17,"HELD - do not run") | H7: =SUM(C7:G7)
A8: Assets | B8: 9 | C8: =COUNTIF('Assets'!$K$2:$K$10,"Pass") | D8: =COUNTIF('Assets'!$K$2:$K$10,"Fail") | E8: =COUNTIF('Assets'!$K$2:$K$10,"Blocked") | F8: =COUNTIF('Assets'!$K$2:$K$10,"Not run") | G8: =COUNTIF('Assets'!$K$2:$K$10,"HELD - do not run") | H8: =SUM(C8:G8)
A9: Parts | B9: 12 | C9: =COUNTIF('Parts'!$K$2:$K$13,"Pass") | D9: =COUNTIF('Parts'!$K$2:$K$13,"Fail") | E9: =COUNTIF('Parts'!$K$2:$K$13,"Blocked") | F9: =COUNTIF('Parts'!$K$2:$K$13,"Not run") | G9: =COUNTIF('Parts'!$K$2:$K$13,"HELD - do not run") | H9: =SUM(C9:G9)
A10: Vendors | B10: 12 | C10: =COUNTIF('Vendors'!$K$2:$K$13,"Pass") | D10: =COUNTIF('Vendors'!$K$2:$K$13,"Fail") | E10: =COUNTIF('Vendors'!$K$2:$K$13,"Blocked") | F10: =COUNTIF('Vendors'!$K$2:$K$13,"Not run") | G10: =COUNTIF('Vendors'!$K$2:$K$13,"HELD - do not run") | H10: =SUM(C10:G10)
A11: Part Sales | B11: 9 | C11: =COUNTIF('Part Sales'!$K$2:$K$10,"Pass") | D11: =COUNTIF('Part Sales'!$K$2:$K$10,"Fail") | E11: =COUNTIF('Part Sales'!$K$2:$K$10,"Blocked") | F11: =COUNTIF('Part Sales'!$K$2:$K$10,"Not run") | G11: =COUNTIF('Part Sales'!$K$2:$K$10,"HELD - do not run") | H11: =SUM(C11:G11)
A12: Purchase Orders | B12: 11 | C12: =COUNTIF('Purchase Orders'!$K$2:$K$12,"Pass") | D12: =COUNTIF('Purchase Orders'!$K$2:$K$12,"Fail") | E12: =COUNTIF('Purchase Orders'!$K$2:$K$12,"Blocked") | F12: =COUNTIF('Purchase Orders'!$K$2:$K$12,"Not run") | G12: =COUNTIF('Purchase Orders'!$K$2:$K$12,"HELD - do not run") | H12: =SUM(C12:G12)
A13: Vendor Invoices | B13: 8 | C13: =COUNTIF('Vendor Invoices'!$K$2:$K$9,"Pass") | D13: =COUNTIF('Vendor Invoices'!$K$2:$K$9,"Fail") | E13: =COUNTIF('Vendor Invoices'!$K$2:$K$9,"Blocked") | F13: =COUNTIF('Vendor Invoices'!$K$2:$K$9,"Not run") | G13: =COUNTIF('Vendor Invoices'!$K$2:$K$9,"HELD - do not run") | H13: =SUM(C13:G13)
A14: All tab and cross-tab | B14: 22 | C14: =COUNTIF('All tab and cross-tab'!$K$2:$K$23,"Pass") | D14: =COUNTIF('All tab and cross-tab'!$K$2:$K$23,"Fail") | E14: =COUNTIF('All tab and cross-tab'!$K$2:$K$23,"Blocked") | F14: =COUNTIF('All tab and cross-tab'!$K$2:$K$23,"Not run") | G14: =COUNTIF('All tab and cross-tab'!$K$2:$K$23,"HELD - do not run") | H14: =SUM(C14:G14)
A15: TOTAL | B15: =SUM(B6:B14) | C15: =SUM(C6:C14) | D15: =SUM(D6:D14) | E15: =SUM(E6:E14) | F15: =SUM(F6:F14) | G15: =SUM(G6:G14) | H15: =SUM(H6:H14)
A17: The "Held" column counts tests the specification cannot yet answer. They are question Q1 on the "Questions for the PO" tab — they are not failures and must not be reported as any result until that question is answered.

Sheet Work Orders
A1: ID | B1: TestRail | C1: What you are checking | D1: Why it matters to a real user | E1: Before you start | F1: TYPE THIS | G1: What to do | H1: What you should see | I1: Where that comes from | J1: The exact wording of the requirement | K1: Result | L1: What you actually saw | M1: Ticket
A2: SRI-WO-A1 | B2: C146197 | C2: The whole matched value is shown, not just what you typed | D2: If the row shows only the characters I typed, I am reading my own query back. It tells me nothing about which record this is. | E2: A work order exists whose WO number contains this fragment somewhere other than the very start. NOTE: 2 rows come back sharing this fragment — perfect for this test | F2: ZZLONGROW | G2: 1. Open search and type the term in the green cell. 2. Open the Work Orders tab. 3. Look at each row WITHOUT opening it. 4. Write down the WO number exactly as the row shows it. | H2: Each row shows the COMPLETE WO number, with the bit you typed highlighted inside it. Seeing only what you typed, or a value cut short with "...", is a FAIL — that is SV-10619 and SV-10551. | I2: PRD v1.5, section 5.3 | J2: Every row has a left-side entity icon, a primary line (bold), a secondary line (subdued), and an optional right-side cluster (status badges, counts, and quick-action buttons on hover). The matched substring of the query is highlighted in the primary and secondary text — searching `Fib` highlights "Fib" in "S1-644 Fibridge Commercial".
A3: SRI-WO-A2 | B3: C146198 | C3: A long value is not cut off through the part that matched | D3: A row that cuts off at "9..." has hidden the one thing I was looking for. | E3: A work order whose text is long enough to overflow the search box (the box is a fixed width), with the matched characters near the END of the value. | F3: ZZLONGROW | G3: 1. Open search and type the term. 2. Open the Work Orders tab. 3. Look for any text ending in "...". 4. If you see one, write down what is hidden and what you typed. | H3: You can still identify the record. If the "..." has eaten the characters you typed, or eaten the part that tells this record from its neighbours, that is a FAIL. | I3: Story SV-9170 | J3: Each result row carries enough context to pick the right record without opening it — its identifier, who it belongs to, its status, and for work orders the unit number and vehicle, which is what tells two of the same customer's work orders apart.
A4: SRI-WO-A3 | B4: C146199 | C4: The highlight marks the match inside the text, not instead of it | D4: A highlight is meant to point at something. If it replaces the text, it points at nothing. | E4: Any work order you can find by typing part of what the row displays. | F4: ZZLONGROW | G4: 1. Open search and type the term. 2. Open the Work Orders tab. 3. Look at how the match is drawn on the row. | H4: The full text is on the row and the matched part is highlighted within it — exactly like the example in the requirement, where typing "Fib" shows the whole of "S1-644 Fibridge Commercial" with "Fib" marked. | I4: PRD v1.5, section 5.3 | J4: Every row has a left-side entity icon, a primary line (bold), a secondary line (subdued), and an optional right-side cluster (status badges, counts, and quick-action buttons on hover). The matched substring of the query is highlighted in the primary and secondary text — searching `Fib` highlights "Fib" in "S1-644 Fibridge Commercial".
A5: SRI-WO-B1 | B5: C146200 | C5: Two records sharing what you typed can be told apart | D5: This is the whole point. Type 123786 and if two rows both draw as "786", you cannot tell 123786 from 185786 without opening both. | E5: Two work orders exist whose WO number are DIFFERENT but share a run of characters. NOTE: 2 rows come back sharing this fragment — perfect for this test | F5: ZZLONGROW | G5: 1. Open search and type the term. 2. Open the Work Orders tab. 3. WITHOUT opening anything, write down which row is which. 4. If you cannot tell them apart, that is the failure — say so. | H5: You can say which row is which from the rows alone. Two rows that read the same is a FAIL — and note that the right number of rows does not rescue it. | I5: Story SV-9170 | J5: Each result row carries enough context to pick the right record without opening it — its identifier, who it belongs to, its status, and for work orders the unit number and vehicle, which is what tells two of the same customer's work orders apart.
A6: SRI-WO-B2 | B6: C146201 | C6: Two records with the same bold line differ somewhere you can see | D6: Real shops have two trucks of the same year/make/model and two vendors with the same name. If the rows are identical the list is useless. | E6: Two work orders whose bold first line is identical but which are different records. These were seeded for this suite. NOTE: 2 rows come back; at least two carry the same bold line | F6: ZZLONGROW | G6: 1. Open search and type the term. 2. Open the Work Orders tab. 3. Compare the two rows line by line. 4. Write down what, if anything, separates them. | H6: Something visible differs — the second line, a badge, a number. Two identical rows is a FAIL; write down both records and what actually differs between them in the data. | I6: Story SV-9170 | J6: Each result row carries enough context to pick the right record without opening it — its identifier, who it belongs to, its status, and for work orders the unit number and vehicle, which is what tells two of the same customer's work orders apart.
A7: SRI-WO-C1 | B7: C146202 | C7: A match on VIN / serial number shows the FULL value on the row | D7: a service advisor reads the VIN off the windscreen or the customer reads it down the phone | E7: A work order carrying a distinctive value in VIN / serial number — a value that appears in NO other field of that record. NOTE: proven to match on vin (exact) | F7: SVEWU82M5ETEJFWFA | G7: 1. Open search and type the term. 2. Open the Work Orders tab. 3. Find the record. Without opening it, read the SECOND line of the row. 4. It should carry a labelled note naming the field that matched. 5. Now check the value in that note against the record itself. | H7: The second line carries a labelled note — such as "Contact match: ...", "Matched: ...", "Unit: ...", "VIN: ..." — naming what matched, with the part you typed highlighted inside it. THE THING TO CHECK IS WHETHER THE VALUE IS COMPLETE. The note must show the WHOLE VIN / serial number value, not just the characters you typed. Open the record and compare. If you typed part of a longer value and the note shows only that part, this is a FAIL — it is SV-10619 and SV-10551, and it means two different records can draw identically. | I7: PRD v1.5, section 5.3 | J7: Every row has a left-side entity icon, a primary line (bold), a secondary line (subdued), and an optional right-side cluster (status badges, counts, and quick-action buttons on hover). The matched substring of the query is highlighted in the primary and secondary text — searching `Fib` highlights "Fib" in "S1-644 Fibridge Commercial".
A8: SRI-WO-C2 | B8: C195898 | C8: A match on lead technician name shows the FULL value on the row | D8: a foreman looks for "the job Danny is on" | E8: A work order carrying a distinctive value in lead technician name — a value that appears in NO other field of that record. NOTE: proven to match on lead_technician_name (word) | F8: Muzamil | G8: 1. Open search and type the term. 2. Open the Work Orders tab. 3. Find the record. Without opening it, read the SECOND line of the row. 4. It should carry a labelled note naming the field that matched. 5. Now check the value in that note against the record itself. | H8: The second line carries a labelled note — such as "Contact match: ...", "Matched: ...", "Unit: ...", "VIN: ..." — naming what matched, with the part you typed highlighted inside it. THE THING TO CHECK IS WHETHER THE VALUE IS COMPLETE. The note must show the WHOLE lead technician name value, not just the characters you typed. Open the record and compare. If you typed part of a longer value and the note shows only that part, this is a FAIL — it is SV-10619 and SV-10551, and it means two different records can draw identically. | I8: PRD v1.5, section 5.3 | J8: Every row has a left-side entity icon, a primary line (bold), a secondary line (subdued), and an optional right-side cluster (status badges, counts, and quick-action buttons on hover). The matched substring of the query is highlighted in the primary and secondary text — searching `Fib` highlights "Fib" in "S1-644 Fibridge Commercial".
A9: SRI-WO-C3 | B9: C146204 | C9: A match on service advisor name shows the FULL value on the row | D9: a manager looks for the jobs one advisor wrote up | E9: A work order carrying a distinctive value in service advisor name — a value that appears in NO other field of that record. NOTE: proven to match on service_advisor_name (word) | F9: Veljkovic | G9: 1. Open search and type the term. 2. Open the Work Orders tab. 3. Find the record. Without opening it, read the SECOND line of the row. 4. It should carry a labelled note naming the field that matched. 5. Now check the value in that note against the record itself. | H9: The second line carries a labelled note — such as "Contact match: ...", "Matched: ...", "Unit: ...", "VIN: ..." — naming what matched, with the part you typed highlighted inside it. THE THING TO CHECK IS WHETHER THE VALUE IS COMPLETE. The note must show the WHOLE service advisor name value, not just the characters you typed. Open the record and compare. If you typed part of a longer value and the note shows only that part, this is a FAIL — it is SV-10619 and SV-10551, and it means two different records can draw identically. | I9: PRD v1.5, section 5.3 | J9: Every row has a left-side entity icon, a primary line (bold), a secondary line (subdued), and an optional right-side cluster (status badges, counts, and quick-action buttons on hover). The matched substring of the query is highlighted in the primary and secondary text — searching `Fib` highlights "Fib" in "S1-644 Fibridge Commercial".
A10: SRI-WO-C4 | B10: C146205 | C10: A match on line item descriptions (parts and labor on the WO) shows the FULL value on the row | D10: a parts person asks "which job did that alternator go on?" | E10: A work order carrying a distinctive value in line item descriptions (parts and labor on the WO) — a value that appears in NO other field of that record. NOTE: 5 rows come back sharing this | F10: 786 | G10: 1. Open search and type the term. 2. Open the Work Orders tab. 3. Find the record. Without opening it, read the SECOND line of the row. 4. It should carry a labelled note naming the field that matched. 5. Now check the value in that note against the record itself. | H10: The second line carries a labelled note — such as "Contact match: ...", "Matched: ...", "Unit: ...", "VIN: ..." — naming what matched, with the part you typed highlighted inside it. THE THING TO CHECK IS WHETHER THE VALUE IS COMPLETE. The note must show the WHOLE line item descriptions (parts and labor on the WO) value, not just the characters you typed. Open the record and compare. If you typed part of a longer value and the note shows only that part, this is a FAIL — it is SV-10619 and SV-10551, and it means two different records can draw identically. | I10: PRD v1.5, section 5.3 | J10: Every row has a left-side entity icon, a primary line (bold), a secondary line (subdued), and an optional right-side cluster (status badges, counts, and quick-action buttons on hover). The matched substring of the query is highlighted in the primary and secondary text — searching `Fib` highlights "Fib" in "S1-644 Fibridge Commercial".
A11: SRI-WO-C5 | B11: C146206 | C11: A match on part numbers on the work order's lines (`item_part_numbers`) shows the FULL value on the row | D11: the same question asked with the number instead of the name | E11: A work order carrying a distinctive value in part numbers on the work order's lines (`item_part_numbers`) — a value that appears in NO other field of that record. NOTE: 2 rows come back sharing this | F11: 786 | G11: 1. Open search and type the term. 2. Open the Work Orders tab. 3. Find the record. Without opening it, read the SECOND line of the row. 4. It should carry a labelled note naming the field that matched. 5. Now check the value in that note against the record itself. | H11: The second line carries a labelled note — such as "Contact match: ...", "Matched: ...", "Unit: ...", "VIN: ..." — naming what matched, with the part you typed highlighted inside it. THE THING TO CHECK IS WHETHER THE VALUE IS COMPLETE. The note must show the WHOLE part numbers on the work order's lines (`item_part_numbers`) value, not just the characters you typed. Open the record and compare. If you typed part of a longer value and the note shows only that part, this is a FAIL — it is SV-10619 and SV-10551, and it means two different records can draw identically. | I11: PRD v1.5, section 5.3 | J11: Every row has a left-side entity icon, a primary line (bold), a secondary line (subdued), and an optional right-side cluster (status badges, counts, and quick-action buttons on hover). The matched substring of the query is highlighted in the primary and secondary text — searching `Fib` highlights "Fib" in "S1-644 Fibridge Commercial".
A12: SRI-WO-D1 | B12: C146207 | C12: The Work Orders row shows everything the specification promised | D12: Each field is there because somebody decided you need it to choose. A missing one is a choice you now have to make by opening records. | E12: Any work order that search returns, which has a value in each field named in the requirement column. | F12: ZZLONGROW | G12: 1. Open search and type something that returns the record. 2. Open the Work Orders tab. 3. Check the row against the requirement column, field by field. 4. Tick off each one. Write down any that is missing. | H12: Every field named in the requirement is on the row. Do not judge whether a missing one matters — just record it. | I12: PRD v1.5, section 4 | J12: Displayed: WO number + customer name (primary), status badge, **unit number + year/make/model**. When the asset has no unit number, the year/make/model stands alone.
A13: SRI-WO-I1 | B13: C146208 | C13: A corrected typo says that it corrected something | D13: If the system quietly fixes my typo without saying so, I will think I found an exact match and act on the wrong record. | E13: A work order whose name or description can be found by spelling it slightly wrong (one or two letters out). Do NOT use a number or a code — those are excluded on purpose. NOTE: checked on this environment: typing this brings back 'S10740-17625', whose name is a near-miss of what you typed, and it should be drawn as a SOFT match. That soft row is the one this test is about — not the exact matches above it. | F13: ZZSOFTHIT | G13: 1. Open search and type the near-miss spelling. 2. Open the Work Orders tab. 3. Look closely at the matched word. | H13: The matched word is highlighted AND carries the "≈" mark or italics that says it is a close match. A corrected typo that looks exactly like an exact match is a FAIL. | I13: PRD v1.5, section 7 | J13: When a match is fuzzy rather than exact, the matched token in the row is still highlighted, and a subtle `≈` or italicized treatment indicates the soft match.

Sheet Customers
A1: ID | B1: TestRail | C1: What you are checking | D1: Why it matters to a real user | E1: Before you start | F1: TYPE THIS | G1: What to do | H1: What you should see | I1: Where that comes from | J1: The exact wording of the requirement | K1: Result | L1: What you actually saw | M1: Ticket
A2: SRI-CUST-A1 | B2: C146209 | C2: The whole matched value is shown, not just what you typed | D2: If the row shows only the characters I typed, I am reading my own query back. It tells me nothing about which record this is. | E2: A customer exists whose telephone contains this fragment somewhere other than the very start. NOTE: 3 rows come back sharing this fragment — perfect for this test | F2: ZZLONGROW | G2: 1. Open search and type the term in the green cell. 2. Open the Customers tab. 3. Look at each row WITHOUT opening it. 4. Write down the telephone exactly as the row shows it. | H2: Each row shows the COMPLETE telephone, with the bit you typed highlighted inside it. Seeing only what you typed, or a value cut short with "...", is a FAIL — that is SV-10619 and SV-10551. | I2: PRD v1.5, section 5.3 | J2: Every row has a left-side entity icon, a primary line (bold), a secondary line (subdued), and an optional right-side cluster (status badges, counts, and quick-action buttons on hover). The matched substring of the query is highlighted in the primary and secondary text — searching `Fib` highlights "Fib" in "S1-644 Fibridge Commercial".
A3: SRI-CUST-A2 | B3: C146210 | C3: A long value is not cut off through the part that matched | D3: A row that cuts off at "9..." has hidden the one thing I was looking for. | E3: A customer whose text is long enough to overflow the search box (the box is a fixed width), with the matched characters near the END of the value. | F3: ZZLONGROW | G3: 1. Open search and type the term. 2. Open the Customers tab. 3. Look for any text ending in "...". 4. If you see one, write down what is hidden and what you typed. | H3: You can still identify the record. If the "..." has eaten the characters you typed, or eaten the part that tells this record from its neighbours, that is a FAIL. | I3: Story SV-9170 | J3: Each result row carries enough context to pick the right record without opening it — its identifier, who it belongs to, its status, and for work orders the unit number and vehicle, which is what tells two of the same customer's work orders apart.
A4: SRI-CUST-A3 | B4: C146211 | C4: The highlight marks the match inside the text, not instead of it | D4: A highlight is meant to point at something. If it replaces the text, it points at nothing. | E4: Any customer you can find by typing part of what the row displays. | F4: ZZLONGROW | G4: 1. Open search and type the term. 2. Open the Customers tab. 3. Look at how the match is drawn on the row. | H4: The full text is on the row and the matched part is highlighted within it — exactly like the example in the requirement, where typing "Fib" shows the whole of "S1-644 Fibridge Commercial" with "Fib" marked. | I4: PRD v1.5, section 5.3 | J4: Every row has a left-side entity icon, a primary line (bold), a secondary line (subdued), and an optional right-side cluster (status badges, counts, and quick-action buttons on hover). The matched substring of the query is highlighted in the primary and secondary text — searching `Fib` highlights "Fib" in "S1-644 Fibridge Commercial".
A5: SRI-CUST-B1 | B5: C146212 | C5: Two records sharing what you typed can be told apart | D5: This is the whole point. Type 123786 and if two rows both draw as "786", you cannot tell 123786 from 185786 without opening both. | E5: Two customers exist whose telephone are DIFFERENT but share a run of characters. NOTE: 3 rows come back sharing this fragment — perfect for this test | F5: ZZLONGROW | G5: 1. Open search and type the term. 2. Open the Customers tab. 3. WITHOUT opening anything, write down which row is which. 4. If you cannot tell them apart, that is the failure — say so. | H5: You can say which row is which from the rows alone. Two rows that read the same is a FAIL — and note that the right number of rows does not rescue it. | I5: Story SV-9170 | J5: Each result row carries enough context to pick the right record without opening it — its identifier, who it belongs to, its status, and for work orders the unit number and vehicle, which is what tells two of the same customer's work orders apart.
A6: SRI-CUST-B2 | B6: C146213 | C6: Two records with the same bold line differ somewhere you can see | D6: Real shops have two trucks of the same year/make/model and two vendors with the same name. If the rows are identical the list is useless. | E6: Two DIFFERENT customers, each holding a contact with the SAME name. Searching that name returns both customer rows, and both carry the identical line "Contact match: ZZSAMEREP". The product will not allow two customers with the same name, so this is the real shape of the risk on this tab. NOTE: 2 rows come back; at least two carry the same bold line | F6: ZZSAMEREP | G6: 1. Open search and type the term. 2. Open the Customers tab. 3. Compare the two rows line by line. 4. Write down what, if anything, separates them. | H6: Something visible differs — the second line, a badge, a number. Two identical rows is a FAIL; write down both records and what actually differs between them in the data. | I6: Story SV-9170 | J6: Each result row carries enough context to pick the right record without opening it — its identifier, who it belongs to, its status, and for work orders the unit number and vehicle, which is what tells two of the same customer's work orders apart.
A7: SRI-CUST-C1 | B7: C146214 | C7: A match on the customer's own telephone shows the FULL value on the row | D7: the single most common way a service advisor finds a caller — and the PRD asks for it on hover, which the build does not do at all | E7: A customer carrying a distinctive value in the customer's own telephone — a value that appears in NO other field of that record. NOTE: proven to match on phone (exact) | F7: 730-246-8895 | G7: 1. Open search and type the term. 2. Open the Customers tab. 3. Find the record. Without opening it, read the SECOND line of the row. 4. It should carry a labelled note naming the field that matched. 5. Now check the value in that note against the record itself. | H7: The second line carries a labelled note — such as "Contact match: ...", "Matched: ...", "Unit: ...", "VIN: ..." — naming what matched, with the part you typed highlighted inside it. THE THING TO CHECK IS WHETHER THE VALUE IS COMPLETE. The note must show the WHOLE the customer's own telephone value, not just the characters you typed. Open the record and compare. If you typed part of a longer value and the note shows only that part, this is a FAIL — it is SV-10619 and SV-10551, and it means two different records can draw identically. | I7: PRD v1.5, section 5.3 | J7: Every row has a left-side entity icon, a primary line (bold), a secondary line (subdued), and an optional right-side cluster (status badges, counts, and quick-action buttons on hover). The matched substring of the query is highlighted in the primary and secondary text — searching `Fib` highlights "Fib" in "S1-644 Fibridge Commercial".
A8: SRI-CUST-C2 | B8: C146215 | C8: A match on a contact's telephone shows the FULL value on the row | D8: the person calling is an employee of the company, not the company | E8: A customer carrying a distinctive value in a contact's telephone — a value that appears in NO other field of that record. NOTE: proven to match on contact_phones (exact) | F8: 898-021-4480 | G8: 1. Open search and type the term. 2. Open the Customers tab. 3. Find the record. Without opening it, read the SECOND line of the row. 4. It should carry a labelled note naming the field that matched. 5. Now check the value in that note against the record itself. | H8: The second line carries a labelled note — such as "Contact match: ...", "Matched: ...", "Unit: ...", "VIN: ..." — naming what matched, with the part you typed highlighted inside it. THE THING TO CHECK IS WHETHER THE VALUE IS COMPLETE. The note must show the WHOLE a contact's telephone value, not just the characters you typed. Open the record and compare. If you typed part of a longer value and the note shows only that part, this is a FAIL — it is SV-10619 and SV-10551, and it means two different records can draw identically. | I8: PRD v1.5, section 5.3 | J8: Every row has a left-side entity icon, a primary line (bold), a secondary line (subdued), and an optional right-side cluster (status badges, counts, and quick-action buttons on hover). The matched substring of the query is highlighted in the primary and secondary text — searching `Fib` highlights "Fib" in "S1-644 Fibridge Commercial".
A9: SRI-CUST-C3 | B9: C146216 | C9: A match on a contact's email address shows the FULL value on the row | D9: the enquiry arrived by email | E9: A customer carrying a distinctive value in a contact's email address — a value that appears in NO other field of that record. NOTE: proven to match on contact_emails (exact) | F9: savannah.tran@staging.shopview.local | G9: 1. Open search and type the term. 2. Open the Customers tab. 3. Find the record. Without opening it, read the SECOND line of the row. 4. It should carry a labelled note naming the field that matched. 5. Now check the value in that note against the record itself. | H9: The second line carries a labelled note — such as "Contact match: ...", "Matched: ...", "Unit: ...", "VIN: ..." — naming what matched, with the part you typed highlighted inside it. THE THING TO CHECK IS WHETHER THE VALUE IS COMPLETE. The note must show the WHOLE a contact's email address value, not just the characters you typed. Open the record and compare. If you typed part of a longer value and the note shows only that part, this is a FAIL — it is SV-10619 and SV-10551, and it means two different records can draw identically. | I9: PRD v1.5, section 5.3 | J9: Every row has a left-side entity icon, a primary line (bold), a secondary line (subdued), and an optional right-side cluster (status badges, counts, and quick-action buttons on hover). The matched substring of the query is highlighted in the primary and secondary text — searching `Fib` highlights "Fib" in "S1-644 Fibridge Commercial".
A10: SRI-CUST-C4 | B10: C146217 | C10: A match on a contact's name shows the FULL value on the row | D10: the caller gives their own name, not the company name | E10: A customer carrying a distinctive value in a contact's name — a value that appears in NO other field of that record. NOTE: proven to match on contact_names (word) | F10: Savannah | G10: 1. Open search and type the term. 2. Open the Customers tab. 3. Find the record. Without opening it, read the SECOND line of the row. 4. It should carry a labelled note naming the field that matched. 5. Now check the value in that note against the record itself. | H10: The second line carries a labelled note — such as "Contact match: ...", "Matched: ...", "Unit: ...", "VIN: ..." — naming what matched, with the part you typed highlighted inside it. THE THING TO CHECK IS WHETHER THE VALUE IS COMPLETE. The note must show the WHOLE a contact's name value, not just the characters you typed. Open the record and compare. If you typed part of a longer value and the note shows only that part, this is a FAIL — it is SV-10619 and SV-10551, and it means two different records can draw identically. | I10: PRD v1.5, section 5.3 | J10: Every row has a left-side entity icon, a primary line (bold), a secondary line (subdued), and an optional right-side cluster (status badges, counts, and quick-action buttons on hover). The matched substring of the query is highlighted in the primary and secondary text — searching `Fib` highlights "Fib" in "S1-644 Fibridge Commercial".
A11: SRI-CUST-C5 | B11: C146218 | C11: A match on address line 2 shows the FULL value on the row | D11: a suite or unit number distinguishes two customers at one street address | E11: A customer carrying a distinctive value in address line 2 — a value that appears in NO other field of that record. NOTE: proven to match on address_line_2 (word) | F11: Apt. 199 | G11: 1. Open search and type the term. 2. Open the Customers tab. 3. Find the record. Without opening it, read the SECOND line of the row. 4. It should carry a labelled note naming the field that matched. 5. Now check the value in that note against the record itself. | H11: The second line carries a labelled note — such as "Contact match: ...", "Matched: ...", "Unit: ...", "VIN: ..." — naming what matched, with the part you typed highlighted inside it. THE THING TO CHECK IS WHETHER THE VALUE IS COMPLETE. The note must show the WHOLE address line 2 value, not just the characters you typed. Open the record and compare. If you typed part of a longer value and the note shows only that part, this is a FAIL — it is SV-10619 and SV-10551, and it means two different records can draw identically. | I11: PRD v1.5, section 5.3 | J11: Every row has a left-side entity icon, a primary line (bold), a secondary line (subdued), and an optional right-side cluster (status badges, counts, and quick-action buttons on hover). The matched substring of the query is highlighted in the primary and secondary text — searching `Fib` highlights "Fib" in "S1-644 Fibridge Commercial".
A12: SRI-CUST-C6 | B12: C195899 | C12: A match on city shows the FULL value on the row | D12: two customers share a name and differ only by town | E12: A customer carrying a distinctive value in city — a value that appears in NO other field of that record. NOTE: proven to match on city (fuzzy) | F12: Raystad | G12: 1. Open search and type the term. 2. Open the Customers tab. 3. Find the record. Without opening it, read the SECOND line of the row. 4. It should carry a labelled note naming the field that matched. 5. Now check the value in that note against the record itself. | H12: The second line carries a labelled note — such as "Contact match: ...", "Matched: ...", "Unit: ...", "VIN: ..." — naming what matched, with the part you typed highlighted inside it. THE THING TO CHECK IS WHETHER THE VALUE IS COMPLETE. The note must show the WHOLE city value, not just the characters you typed. Open the record and compare. If you typed part of a longer value and the note shows only that part, this is a FAIL — it is SV-10619 and SV-10551, and it means two different records can draw identically. | I12: PRD v1.5, section 5.3 | J12: Every row has a left-side entity icon, a primary line (bold), a secondary line (subdued), and an optional right-side cluster (status badges, counts, and quick-action buttons on hover). The matched substring of the query is highlighted in the primary and secondary text — searching `Fib` highlights "Fib" in "S1-644 Fibridge Commercial".
A13: SRI-CUST-C7 | B13: C146220 | C13: A match on state / province shows the FULL value on the row | D13: the same, one level up | E13: A customer carrying a distinctive value in state / province — a value that appears in NO other field of that record. NOTE: proven to match on state (word) | F13: ZZQUEBEXA | G13: 1. Open search and type the term. 2. Open the Customers tab. 3. Find the record. Without opening it, read the SECOND line of the row. 4. It should carry a labelled note naming the field that matched. 5. Now check the value in that note against the record itself. | H13: The second line carries a labelled note — such as "Contact match: ...", "Matched: ...", "Unit: ...", "VIN: ..." — naming what matched, with the part you typed highlighted inside it. THE THING TO CHECK IS WHETHER THE VALUE IS COMPLETE. The note must show the WHOLE state / province value, not just the characters you typed. Open the record and compare. If you typed part of a longer value and the note shows only that part, this is a FAIL — it is SV-10619 and SV-10551, and it means two different records can draw identically. | I13: PRD v1.5, section 5.3 | J13: Every row has a left-side entity icon, a primary line (bold), a secondary line (subdued), and an optional right-side cluster (status badges, counts, and quick-action buttons on hover). The matched substring of the query is highlighted in the primary and secondary text — searching `Fib` highlights "Fib" in "S1-644 Fibridge Commercial".
... A17: SRI-CUST-I1 | B17: C146223 | C17: A corrected typo says that it corrected something | D17: If the system quietly fixes my typo without saying so, I will think I found an exact match and act on the wrong record. | E17: A customer whose name or description can be found by spelling it slightly wrong (one or two letters out). Do NOT use a number or a code — those are excluded on purpose. NOTE: checked on this environment: typing this brings back 'ZZPREFIX Freight Ltd', whose name is a near-miss of what you typed, and it should be drawn as a SOFT match. That soft row is the one this test is about — not the exact matches above it. | F17: ZZPREFIY | G17: 1. Open search and type the near-miss spelling. 2. Open the Customers tab. 3. Look closely at the matched word. | H17: The matched word is highlighted AND carries the "≈" mark or italics that says it is a close match. A corrected typo that looks exactly like an exact match is a FAIL. | I17: PRD v1.5, section 7 | J17: When a match is fuzzy rather than exact, the matched token in the row is still highlighted, and a subtle `≈` or italicized treatment indicates the soft match.

Sheet Assets
A1: ID | B1: TestRail | C1: What you are checking | D1: Why it matters to a real user | E1: Before you start | F1: TYPE THIS | G1: What to do | H1: What you should see | I1: Where that comes from | J1: The exact wording of the requirement | K1: Result | L1: What you actually saw | M1: Ticket
A2: SRI-ASSET-A1 | B2: C146224 | C2: The whole matched value is shown, not just what you typed | D2: If the row shows only the characters I typed, I am reading my own query back. It tells me nothing about which record this is. | E2: A asset exists whose unit number contains this fragment somewhere other than the very start. NOTE: 2 rows come back sharing this fragment — perfect for this test | F2: ZZLONGROW | G2: 1. Open search and type the term in the green cell. 2. Open the Assets tab. 3. Look at each row WITHOUT opening it. 4. Write down the unit number exactly as the row shows it. | H2: Each row shows the COMPLETE unit number, with the bit you typed highlighted inside it. Seeing only what you typed, or a value cut short with "...", is a FAIL — that is SV-10619 and SV-10551. | I2: PRD v1.5, section 5.3 | J2: Every row has a left-side entity icon, a primary line (bold), a secondary line (subdued), and an optional right-side cluster (status badges, counts, and quick-action buttons on hover). The matched substring of the query is highlighted in the primary and secondary text — searching `Fib` highlights "Fib" in "S1-644 Fibridge Commercial".
A3: SRI-ASSET-A2 | B3: C146225 | C3: A long value is not cut off through the part that matched | D3: A row that cuts off at "9..." has hidden the one thing I was looking for. | E3: A asset whose text is long enough to overflow the search box (the box is a fixed width), with the matched characters near the END of the value. | F3: ZZLONGROW | G3: 1. Open search and type the term. 2. Open the Assets tab. 3. Look for any text ending in "...". 4. If you see one, write down what is hidden and what you typed. | H3: You can still identify the record. If the "..." has eaten the characters you typed, or eaten the part that tells this record from its neighbours, that is a FAIL. | I3: Story SV-9170 | J3: Each result row carries enough context to pick the right record without opening it — its identifier, who it belongs to, its status, and for work orders the unit number and vehicle, which is what tells two of the same customer's work orders apart.
A4: SRI-ASSET-A3 | B4: C146226 | C4: The highlight marks the match inside the text, not instead of it | D4: A highlight is meant to point at something. If it replaces the text, it points at nothing. | E4: Any asset you can find by typing part of what the row displays. | F4: ZZLONGROW | G4: 1. Open search and type the term. 2. Open the Assets tab. 3. Look at how the match is drawn on the row. | H4: The full text is on the row and the matched part is highlighted within it — exactly like the example in the requirement, where typing "Fib" shows the whole of "S1-644 Fibridge Commercial" with "Fib" marked. | I4: PRD v1.5, section 5.3 | J4: Every row has a left-side entity icon, a primary line (bold), a secondary line (subdued), and an optional right-side cluster (status badges, counts, and quick-action buttons on hover). The matched substring of the query is highlighted in the primary and secondary text — searching `Fib` highlights "Fib" in "S1-644 Fibridge Commercial".
A5: SRI-ASSET-B1 | B5: C146227 | C5: Two records sharing what you typed can be told apart | D5: This is the whole point. Type 123786 and if two rows both draw as "786", you cannot tell 123786 from 185786 without opening both. | E5: Two assets exist whose unit number are DIFFERENT but share a run of characters. NOTE: 2 rows come back sharing this fragment — perfect for this test | F5: ZZLONGROW | G5: 1. Open search and type the term. 2. Open the Assets tab. 3. WITHOUT opening anything, write down which row is which. 4. If you cannot tell them apart, that is the failure — say so. | H5: You can say which row is which from the rows alone. Two rows that read the same is a FAIL — and note that the right number of rows does not rescue it. | I5: Story SV-9170 | J5: Each result row carries enough context to pick the right record without opening it — its identifier, who it belongs to, its status, and for work orders the unit number and vehicle, which is what tells two of the same customer's work orders apart.
A6: SRI-ASSET-B2 | B6: C146228 | C6: Two records with the same bold line differ somewhere you can see | D6: Real shops have two trucks of the same year/make/model and two vendors with the same name. If the rows are identical the list is useless. | E6: Two assets whose bold first line is identical but which are different records. These were seeded for this suite. NOTE: 2 rows come back; at least two carry the same bold line | F6: ZZLONGROW | G6: 1. Open search and type the term. 2. Open the Assets tab. 3. Compare the two rows line by line. 4. Write down what, if anything, separates them. | H6: Something visible differs — the second line, a badge, a number. Two identical rows is a FAIL; write down both records and what actually differs between them in the data. | I6: Story SV-9170 | J6: Each result row carries enough context to pick the right record without opening it — its identifier, who it belongs to, its status, and for work orders the unit number and vehicle, which is what tells two of the same customer's work orders apart.
A7: SRI-ASSET-C1 | B7: C146229 | C7: A match on VIN / serial number shows the FULL value on the row | D7: the VIN is how a vehicle is identified on every legal document the shop touches, and it is indexed but never shown | E7: A asset carrying a distinctive value in VIN / serial number — a value that appears in NO other field of that record. NOTE: proven to match on vin (exact) | F7: SVEWU82M5ETEJFWFA | G7: 1. Open search and type the term. 2. Open the Assets tab. 3. Find the record. Without opening it, read the SECOND line of the row. 4. It should carry a labelled note naming the field that matched. 5. Now check the value in that note against the record itself. | H7: The second line carries a labelled note — such as "Contact match: ...", "Matched: ...", "Unit: ...", "VIN: ..." — naming what matched, with the part you typed highlighted inside it. THE THING TO CHECK IS WHETHER THE VALUE IS COMPLETE. The note must show the WHOLE VIN / serial number value, not just the characters you typed. Open the record and compare. If you typed part of a longer value and the note shows only that part, this is a FAIL — it is SV-10619 and SV-10551, and it means two different records can draw identically. | I7: PRD v1.5, section 5.3 | J7: Every row has a left-side entity icon, a primary line (bold), a secondary line (subdued), and an optional right-side cluster (status badges, counts, and quick-action buttons on hover). The matched substring of the query is highlighted in the primary and secondary text — searching `Fib` highlights "Fib" in "S1-644 Fibridge Commercial".
A8: SRI-ASSET-C2 | B8: C146230 | C8: A match on licence plate shows the FULL value on the row | D8: measured on the build and NOT listed in PRD §4 — see PO-QUESTIONS Q5 | E8: A asset carrying a distinctive value in licence plate — a value that appears in NO other field of that record. NOTE: proven to match on licence_plate (exact) | F8: KVQ-2870 | G8: 1. Open search and type the term. 2. Open the Assets tab. 3. Find the record. Without opening it, read the SECOND line of the row. 4. It should carry a labelled note naming the field that matched. 5. Now check the value in that note against the record itself. | H8: The second line carries a labelled note — such as "Contact match: ...", "Matched: ...", "Unit: ...", "VIN: ..." — naming what matched, with the part you typed highlighted inside it. THE THING TO CHECK IS WHETHER THE VALUE IS COMPLETE. The note must show the WHOLE licence plate value, not just the characters you typed. Open the record and compare. If you typed part of a longer value and the note shows only that part, this is a FAIL — it is SV-10619 and SV-10551, and it means two different records can draw identically. | I8: PRD v1.5, section 5.3 | J8: Every row has a left-side entity icon, a primary line (bold), a secondary line (subdued), and an optional right-side cluster (status badges, counts, and quick-action buttons on hover). The matched substring of the query is highlighted in the primary and secondary text — searching `Fib` highlights "Fib" in "S1-644 Fibridge Commercial".
A9: SRI-ASSET-D1 | B9: C146231 | C9: The Assets row shows everything the specification promised | D9: Each field is there because somebody decided you need it to choose. A missing one is a choice you now have to make by opening records. | E9: Any asset that search returns, which has a value in each field named in the requirement column. | F9: ZZLONGROW | G9: 1. Open search and type something that returns the record. 2. Open the Assets tab. 3. Check the row against the requirement column, field by field. 4. Tick off each one. Write down any that is missing. | H9: Every field named in the requirement is on the row. Do not judge whether a missing one matters — just record it. | I9: PRD v1.5, section 4 | J9: Displayed: year + make + model (primary), customer name (secondary, smaller).
A10: SRI-ASSET-I1 | B10: C146232 | C10: A corrected typo says that it corrected something | D10: If the system quietly fixes my typo without saying so, I will think I found an exact match and act on the wrong record. | E10: A asset whose name or description can be found by spelling it slightly wrong (one or two letters out). Do NOT use a number or a code — those are excluded on purpose. NOTE: checked on this environment: typing this brings back '2019 ZZOBSIDIAM Trucks Hauler', whose name is a near-miss of what you typed, and it should be drawn as a SOFT match. That soft row is the one this test is about — not the exact matches above it. | F10: ZZOBSIDIAN | G10: 1. Open search and type the near-miss spelling. 2. Open the Assets tab. 3. Look closely at the matched word. | H10: The matched word is highlighted AND carries the "≈" mark or italics that says it is a close match. A corrected typo that looks exactly like an exact match is a FAIL. | I10: PRD v1.5, section 7 | J10: When a match is fuzzy rather than exact, the matched token in the row is still highlighted, and a subtle `≈` or italicized treatment indicates the soft match.

Sheet Parts
A1: ID | B1: TestRail | C1: What you are checking | D1: Why it matters to a real user | E1: Before you start | F1: TYPE THIS | G1: What to do | H1: What you should see | I1: Where that comes from | J1: The exact wording of the requirement | K1: Result | L1: What you actually saw | M1: Ticket
A2: SRI-PART-A1 | B2: C146233 | C2: The whole matched value is shown, not just what you typed | D2: If the row shows only the characters I typed, I am reading my own query back. It tells me nothing about which record this is. | E2: A part exists whose part number contains this fragment somewhere other than the very start. NOTE: 2 rows come back sharing this fragment — perfect for this test | F2: ZZLONGROW | G2: 1. Open search and type the term in the green cell. 2. Open the Parts tab. 3. Look at each row WITHOUT opening it. 4. Write down the part number exactly as the row shows it. | H2: Each row shows the COMPLETE part number, with the bit you typed highlighted inside it. Seeing only what you typed, or a value cut short with "...", is a FAIL — that is SV-10619 and SV-10551. | I2: PRD v1.5, section 5.3 | J2: Every row has a left-side entity icon, a primary line (bold), a secondary line (subdued), and an optional right-side cluster (status badges, counts, and quick-action buttons on hover). The matched substring of the query is highlighted in the primary and secondary text — searching `Fib` highlights "Fib" in "S1-644 Fibridge Commercial".
A3: SRI-PART-A2 | B3: C146234 | C3: A long value is not cut off through the part that matched | D3: A row that cuts off at "9..." has hidden the one thing I was looking for. | E3: A part whose text is long enough to overflow the search box (the box is a fixed width), with the matched characters near the END of the value. | F3: ZZLONGROW | G3: 1. Open search and type the term. 2. Open the Parts tab. 3. Look for any text ending in "...". 4. If you see one, write down what is hidden and what you typed. | H3: You can still identify the record. If the "..." has eaten the characters you typed, or eaten the part that tells this record from its neighbours, that is a FAIL. | I3: Story SV-9170 | J3: Each result row carries enough context to pick the right record without opening it — its identifier, who it belongs to, its status, and for work orders the unit number and vehicle, which is what tells two of the same customer's work orders apart.
A4: SRI-PART-A3 | B4: C146235 | C4: The highlight marks the match inside the text, not instead of it | D4: A highlight is meant to point at something. If it replaces the text, it points at nothing. | E4: Any part you can find by typing part of what the row displays. | F4: ZZLONGROW | G4: 1. Open search and type the term. 2. Open the Parts tab. 3. Look at how the match is drawn on the row. | H4: The full text is on the row and the matched part is highlighted within it — exactly like the example in the requirement, where typing "Fib" shows the whole of "S1-644 Fibridge Commercial" with "Fib" marked. | I4: PRD v1.5, section 5.3 | J4: Every row has a left-side entity icon, a primary line (bold), a secondary line (subdued), and an optional right-side cluster (status badges, counts, and quick-action buttons on hover). The matched substring of the query is highlighted in the primary and secondary text — searching `Fib` highlights "Fib" in "S1-644 Fibridge Commercial".
A5: SRI-PART-B1 | B5: C146236 | C5: Two records sharing what you typed can be told apart | D5: This is the whole point. Type 123786 and if two rows both draw as "786", you cannot tell 123786 from 185786 without opening both. | E5: Two parts exist whose part number are DIFFERENT but share a run of characters. NOTE: 2 rows come back sharing this fragment — perfect for this test | F5: ZZLONGROW | G5: 1. Open search and type the term. 2. Open the Parts tab. 3. WITHOUT opening anything, write down which row is which. 4. If you cannot tell them apart, that is the failure — say so. | H5: You can say which row is which from the rows alone. Two rows that read the same is a FAIL — and note that the right number of rows does not rescue it. | I5: Story SV-9170 | J5: Each result row carries enough context to pick the right record without opening it — its identifier, who it belongs to, its status, and for work orders the unit number and vehicle, which is what tells two of the same customer's work orders apart.
A6: SRI-PART-B2 | B6: C146237 | C6: Two records with the same bold line differ somewhere you can see | D6: Real shops have two trucks of the same year/make/model and two vendors with the same name. If the rows are identical the list is useless. | E6: Two parts whose bold first line is identical but which are different records. These were seeded for this suite. NOTE: 2 rows come back; at least two carry the same bold line | F6: ZZLONGROW Heavy Duty Air Brake | G6: 1. Open search and type the term. 2. Open the Parts tab. 3. Compare the two rows line by line. 4. Write down what, if anything, separates them. | H6: Something visible differs — the second line, a badge, a number. Two identical rows is a FAIL; write down both records and what actually differs between them in the data. | I6: Story SV-9170 | J6: Each result row carries enough context to pick the right record without opening it — its identifier, who it belongs to, its status, and for work orders the unit number and vehicle, which is what tells two of the same customer's work orders apart.
A7: SRI-PART-C1 | B7: C146238 | C7: A match on bin location shows the FULL value on the row | D7: the whole point of the search is often "where is it?" — the PRD names bin location as indexed and the row never shows it | E7: A part carrying a distinctive value in bin location — a value that appears in NO other field of that record. NOTE: proven to match on bin_location (word) | F7: H3B | G7: 1. Open search and type the term. 2. Open the Parts tab. 3. Find the record. Without opening it, read the SECOND line of the row. 4. It should carry a labelled note naming the field that matched. 5. Now check the value in that note against the record itself. | H7: The second line carries a labelled note — such as "Contact match: ...", "Matched: ...", "Unit: ...", "VIN: ..." — naming what matched, with the part you typed highlighted inside it. THE THING TO CHECK IS WHETHER THE VALUE IS COMPLETE. The note must show the WHOLE bin location value, not just the characters you typed. Open the record and compare. If you typed part of a longer value and the note shows only that part, this is a FAIL — it is SV-10619 and SV-10551, and it means two different records can draw identically. | I7: PRD v1.5, section 5.3 | J7: Every row has a left-side entity icon, a primary line (bold), a secondary line (subdued), and an optional right-side cluster (status badges, counts, and quick-action buttons on hover). The matched substring of the query is highlighted in the primary and secondary text — searching `Fib` highlights "Fib" in "S1-644 Fibridge Commercial".
A8: SRI-PART-C2 | B8: C146239 | C8: A match on manufacturer shows the FULL value on the row | D8: a parts person searches by who makes it | E8: A part carrying a distinctive value in manufacturer — a value that appears in NO other field of that record. NOTE: proven to match on manufacturer (word) | F8: Klondike | G8: 1. Open search and type the term. 2. Open the Parts tab. 3. Find the record. Without opening it, read the SECOND line of the row. 4. It should carry a labelled note naming the field that matched. 5. Now check the value in that note against the record itself. | H8: The second line carries a labelled note — such as "Contact match: ...", "Matched: ...", "Unit: ...", "VIN: ..." — naming what matched, with the part you typed highlighted inside it. THE THING TO CHECK IS WHETHER THE VALUE IS COMPLETE. The note must show the WHOLE manufacturer value, not just the characters you typed. Open the record and compare. If you typed part of a longer value and the note shows only that part, this is a FAIL — it is SV-10619 and SV-10551, and it means two different records can draw identically. | I8: PRD v1.5, section 5.3 | J8: Every row has a left-side entity icon, a primary line (bold), a secondary line (subdued), and an optional right-side cluster (status badges, counts, and quick-action buttons on hover). The matched substring of the query is highlighted in the primary and secondary text — searching `Fib` highlights "Fib" in "S1-644 Fibridge Commercial".
A9: SRI-PART-C3 | B9: C146240 | C9: A match on vendor name shows the FULL value on the row | D9: a parts person searches by who sells it | E9: A part carrying a distinctive value in vendor name — a value that appears in NO other field of that record. NOTE: proven to match on vendor_name (word) | F9: Gibson's Mobile Diesel Repair | G9: 1. Open search and type the term. 2. Open the Parts tab. 3. Find the record. Without opening it, read the SECOND line of the row. 4. It should carry a labelled note naming the field that matched. 5. Now check the value in that note against the record itself. | H9: The second line carries a labelled note — such as "Contact match: ...", "Matched: ...", "Unit: ...", "VIN: ..." — naming what matched, with the part you typed highlighted inside it. THE THING TO CHECK IS WHETHER THE VALUE IS COMPLETE. The note must show the WHOLE vendor name value, not just the characters you typed. Open the record and compare. If you typed part of a longer value and the note shows only that part, this is a FAIL — it is SV-10619 and SV-10551, and it means two different records can draw identically. | I9: PRD v1.5, section 5.3 | J9: Every row has a left-side entity icon, a primary line (bold), a secondary line (subdued), and an optional right-side cluster (status badges, counts, and quick-action buttons on hover). The matched substring of the query is highlighted in the primary and secondary text — searching `Fib` highlights "Fib" in "S1-644 Fibridge Commercial".
A10: SRI-PART-C4 | B10: C146241 | C10: A match on category shows the FULL value on the row | D10: a broad hunt for "brakes" | E10: A part carrying a distinctive value in category — a value that appears in NO other field of that record. NOTE: proven to match on category (word) | F10: HD-Lighting & Electrical | G10: 1. Open search and type the term. 2. Open the Parts tab. 3. Find the record. Without opening it, read the SECOND line of the row. 4. It should carry a labelled note naming the field that matched. 5. Now check the value in that note against the record itself. | H10: The second line carries a labelled note — such as "Contact match: ...", "Matched: ...", "Unit: ...", "VIN: ..." — naming what matched, with the part you typed highlighted inside it. THE THING TO CHECK IS WHETHER THE VALUE IS COMPLETE. The note must show the WHOLE category value, not just the characters you typed. Open the record and compare. If you typed part of a longer value and the note shows only that part, this is a FAIL — it is SV-10619 and SV-10551, and it means two different records can draw identically. | I10: PRD v1.5, section 5.3 | J10: Every row has a left-side entity icon, a primary line (bold), a secondary line (subdued), and an optional right-side cluster (status badges, counts, and quick-action buttons on hover). The matched substring of the query is highlighted in the primary and secondary text — searching `Fib` highlights "Fib" in "S1-644 Fibridge Commercial".
